Workbook
Name __MIN2016: #REF!
Name __PRC1: #REF!
Name _20EURRATE: #REF!
Name _20EURRATE: #REF!
Name _CRN1: [6]Dimensions!#REF!
Name _CRN2: [6]Dimensions!#REF!
Name _DAT4: '[7]Tab 01'!#REF!
Name _LCP2: #REF!
Name _LinkPic_45022E3A814A4CCE8C24E4AE23F9E450: #REF!
Name _ric2: #REF!
Name _ric3: #REF!
Name _TVA1098: #REF!
Name Account_codes: [10]Descriptions!$D$1:$H$787
Name Account_codes: [11]Descriptions!$D$1:$H$787
Name ACE: #REF!
Name AEngagHB: #REF!
Name Andep: [12]GEFFGL!$H$2
Name ANNEE: [13]Feuil1!$B$1
Name Année2: [14]Hypothèses!$E$8
Name Année3: [14]Hypothèses!$E$9
Name ANNEEbis: [13]Feuil1!$B$1
Name archCost: #REF!
Name archCost: #REF!
Name AREP: #REF!
Name AshfordLeaseAssetCfProfile: '[15]nfm-f670-d158 (GreenSpeed)'!#REF!
Name AshfordLeaseAssetCfProfile: '[16]nfm-f670-d158 (GreenSpeed)'!#REF!
Name AshfordLeaseAssetCfProfile: '[16]nfm-f670-d158 (GreenSpeed)'!#REF!
Name AshfordLeaseCurrentAssetCfProfile: '[15]nfm-f670-d158 (GreenSpeed)'!#REF!
Name AshfordLeaseCurrentAssetCfProfile: '[16]nfm-f670-d158 (GreenSpeed)'!#REF!
Name AshfordLeaseCurrentAssetCfProfile: '[16]nfm-f670-d158 (GreenSpeed)'!#REF!
Name AshfordLeaseLongTermCreditorCfProfile: '[15]nfm-f670-d158 (GreenSpeed)'!#REF!
Name AshfordLeaseLongTermCreditorCfProfile: '[16]nfm-f670-d158 (GreenSpeed)'!#REF!
Name AshfordLeaseLongTermCreditorCfProfile: '[16]nfm-f670-d158 (GreenSpeed)'!#REF!
Name AshfordLeaseNonCurrentAssetCfProfile: '[15]nfm-f670-d158 (GreenSpeed)'!#REF!
Name AshfordLeaseNonCurrentAssetCfProfile: '[16]nfm-f670-d158 (GreenSpeed)'!#REF!
Name AshfordLeaseNonCurrentAssetCfProfile: '[16]nfm-f670-d158 (GreenSpeed)'!#REF!
Name AshfordLeaseShortTermCreditorCfProfile: '[15]nfm-f670-d158 (GreenSpeed)'!#REF!
Name AshfordLeaseShortTermCreditorCfProfile: '[16]nfm-f670-d158 (GreenSpeed)'!#REF!
Name AuditFailsStructural: [17]Audit!$F$19
Name AuditFailsStructural: [18]Audit!$F$19
Name axedoc: '[19]passage ca soc-conso'!#REF!
Name azds: [13]Feuil1!$B$1
Name azeas: #REF!
Name azsz: #REF!
Name b: [20]PowerPoint!$D$16
Name Base2: #REF!
Name BaseScenarios: #REF!
Name bb: [21]PowerPoint!$D$16
Name bd: #REF!
Name BELALL1: [22]offre!$K$11
Name BELALL2: [22]offre!$K$12
Name BF_CAVA_PBA_01: '[23]Trains Week'!$C$92
Name BF_CAVA_PBA_02: '[23]Trains Week'!$D$92
Name BF_CAVA_PBA_03: '[23]Trains Week'!$E$92
Name BF_CAVB_MLV_01: '[23]Trains Week'!$C$116
Name BF_CAVB_MLV_02: '[23]Trains Week'!$D$116
Name BF_CAVB_MLV_03: '[23]Trains Week'!$E$116
Name BF_CAVB_PB_01: '[23]Trains Week'!$C$44
Name BF_CAVB_PB_02: '[23]Trains Week'!$D$44
Name BF_CAVB_PB_03: '[23]Trains Week'!$E$44

Sheet Contents
C3: 1 | D3: Budget 2026 Overview | E3: Overview of budget 2026
C4: 2.1 | D4: EIL Opex Costs | E4: Detail of opex in EIL for budget 2026 downloaded directly from financial system.
C5: 2.2 | D5: EIL Cost of Sales | E5: Detail of Cost of sales in EIL for budget 2026 downloaded directly from financial system.
C6: 2.3 | D6: EIL Capex | E6: Detail of Capex in EIL for budget 2026 downloaded directly from financial system.
C7: 3.1 | D7: THIF Opex Costs | E7: Detail of opex in THIF for budget 2026 downloaded directly from financial system.
C8: 3.2 | D8: THIF Cost of Sales | E8: Detail of Cost of sales in THIF for budget 2026 downloaded directly from financial system.
C9: 3.3 | D9: THIF Capex | E9: Detail of Capex in THIF for budget 2026 downloaded directly from financial system.
C10: 4.1 | D10: Simplify Savings | E10: Detail of any simplify savings included in budget 2026 (where applicable)
C11: 4.2 | D11: Simplify Investments | E11: Detail of any simplify investments included in budget 2026 (where applicable)
C12: 5 | D12: FX Rates

Sheet 1. Budget Overview (EUR)
C3: 2026 Budget (excluding simplify) | D3: EIL Budget (excluding simplify) | E3: THIF Budget (excluding simplify) | F3: Simplify savings | G3: EIL Simplify savings | H3: THIF Simplify savings | I3: Simplify investments | J3: 2026 Budget | K3: EIL | L3: THIF | N3: 2026 Budget (2025 rates)
B4: Revenue | O4: n/a - no revenue in budget 2026
B5: Cost of Sales | C5: =SUM(D5:E5) -> 17397371 | D5: ='2.2 EIL COS'!Z3 -> 13274936 | E5: ='3.2 THIF COS'!S1 -> 4122434.5 | J5: =C5+F5+I5 -> 17397371 | K5: =D5+G5+I5 -> 13274936 | L5: =H5+E5 -> 4122434.5 | O5: n/a - no cost of sales in budget 2026
B6: Opex (excluding staff costs) | C6: =SUM(D6:E6) -> 42678201 | D6: ='2.1 EIL Opex'!AB3 -> 22117348 | E6: ='3.1 THIF Opex'!S1 -> 20560853 | F6: =SUM(G6:H6) -> -4356483.2 | G6: ='4.2 Simplify Savings'!AB1 -> -2533219.1 | H6: ='4.2 Simplify Savings'!AB47 -> -1823264 | I6: ='4.1 Simplify Investments '!AB1-I8 -> 466500 | J6: =C6+F6+I6 -> 38788218 | K6: =D6+G6+I6 -> 20050629 | L6: =H6+E6 -> 18737589 | M6: << opex excluding FTE related staff costs | N6: =SUM('[73]8. Group Opex Detail (€ 2025)'!S3:S7) -> 531381.65
B7: Staff costs | C7: =SUM(D7:E7) -> 14577171 | D7: =SUM('Report Data'!C34:C44,'Report Data'!D45)-'4.2 Simplify Savings'!AB3 -> 12081201 | E7: =SUM('Report Data'!C23:C33) -> 2495969.6 | F7: =SUM(G7:H7) -> -125583.48 | G7: ='4.2 Simplify Savings'!AB3 -> -125583.48 | J7: =C7+F7+I7 -> 14451588 | M7: << staff costs are shown net of FTE related simplify savings | O7: << total wageroll cost to be added (post simplify)
B8: Capex | C8: =SUM(D8:E8) -> 31261811 | D8: ='2.3 EIL Capex '!AP3 -> 26992811 | E8: ='3.3 THIF Capex'!F2 -> 4269000 | I8: =SUM('4.1 Simplify Investments '!AB8:AB12) -> 466500 | J8: =C8+F8+I8 -> 31728311 | K8: =D8+G8+I8 -> 27459311 | L8: =H8+E8 -> 4269000 | O8: n/a - no capex in budget 2026

Sheet 2.1 EIL Opex
AA3: Total | AB3: =SUBTOTAL(9,AB5:AB184) -> 22117348 | AC3: =SUBTOTAL(9,AC5:AC184) -> -2533219.1 | AD3: =SUBTOTAL(9,AD5:AD184) -> 19584129
A4: Cost center manager | B4: Is Split Child Row | C4: Level Code | D4: Level Name | E4: Account Code Code | F4: Account Code Name | G4: Counterparty Code | H4: Counterparty Name | I4: Project Code | J4: Project Name | K4: Details (Free Text) | L4: Supplier (Free Text) | M4: Version (Free Text) | N4: Currency | O4: Jan-2026 | P4: Feb-2026 | Q4: Mar-2026 | R4: Apr-2026 | S4: May-2026 | T4: Jun-2026 | U4: Jul-2026 | V4: Aug-2026 | W4: Sep-2026 | X4: Oct-2026 | Y4: Nov-2026 | Z4: Dec-2026 | AA4: FY2026 | AB4: cost in euros | AC4: Simplify savings | AD4: Total after Simplify | AF4: << Column AA and AB are net of Simplify savings and show the allowable spend for budget 2026. Column AD is the budget before simplify with column AC showing the effort to be made per line.
A5: =_xlfn.XLOOKUP(B5*1,'Reference '!I:I,'Reference '!K:K) -> Paolo Rodeghiero | B5: =LEFT(C5,3) -> 608 | C5: 608_Data & Middleware_EIL_EUR | D5: 608_Data & Middleware_EIL_EUR | E5: 305001 - Agency staff & contractors (STATIONS ONLY) | F5: 305001 - Agency staff & contractors (STATIONS ONLY) | G5: 000000_Default | H5: 000000_Default | I5: 0000_Default | J5: 0000_Default | K5: BI Center of Excellence | M5: Budget 2026 | N5: EUR | O5: 23333 | P5: 23333 | Q5: 23333 | R5: 23333 | S5: 23333 | T5: 23333 | U5: 23333 | V5: 23333 | W5: 23333 | X5: 23333 | Y5: 23333 | Z5: 23333 | AA5: 279996 | AB5: =IF(N5="EUR",AA5,IF(N5="GBP",AA5/Rate!$C$3,AA5/Rate!$C$5)) -> 279996 | AC5: =IFERROR(VLOOKUP(K5,'4.2 Simplify Savings'!K:AB,19,0),0) -> 0 | AD5: =SUM(AB5:AC5) -> 279996
A6: =_xlfn.XLOOKUP(B6*1,'Reference '!I:I,'Reference '!K:K) -> Ben Gbeve | B6: =LEFT(C6,3) -> 601 | C6: 601_IS Service Delivery_EIL_GBP | D6: 601_IS Service Delivery_EIL_GBP | E6: 307001 - Staff entertainment | F6: 307001 - Staff entertainment | G6: 000000_Default | H6: 000000_Default | I6: 0000_Default | J6: 0000_Default | K6: Expenses | L6: Various | M6: Budget 2026 | N6: GBP | O6: 150 | P6: 150 | Q6: 150 | R6: 150 | S6: 150 | T6: 150 | U6: 150 | V6: 150 | W6: 150 | X6: 150 | Y6: 150 | Z6: 150 | AA6: 1800 | AB6: =IF(N6="EUR",AA6,IF(N6="GBP",AA6/Rate!$C$3,AA6/Rate!$C$5)) -> 2068.9655 | AC6: =IFERROR(VLOOKUP(K6,'4.2 Simplify Savings'!K:AB,18,0),0) -> 0 | AD6: =SUM(AB6:AC6) -> 2068.9655
A7: =_xlfn.XLOOKUP(B7*1,'Reference '!I:I,'Reference '!K:K) -> Laurent Bellan | B7: =LEFT(C7,3) -> 600 | C7: 600_CIO_EIL_EUR | D7: 600_CIO_EIL_EUR | E7: 307200 - Training | F7: 307200 - Training | G7: 000000_Default | H7: 000000_Default | I7: 0000_Default | J7: 0000_Default | K7: Training | M7: Budget 2026 | N7: EUR | O7: 8443.06 | P7: 8443.06 | Q7: 8443.06 | R7: 8443.06 | S7: 8443.06 | T7: 8443.06 | U7: 8443.06 | V7: 8443.06 | W7: 8443.06 | X7: 8443.06 | Y7: 8443.06 | Z7: 8443.06 | AA7: 101316.72 | AB7: =IF(N7="EUR",AA7,IF(N7="GBP",AA7/Rate!$C$3,AA7/Rate!$C$5)) -> 101316.72 | AC7: =IFERROR(VLOOKUP(K7,'4.2 Simplify Savings'!K:AB,18,0),0) -> 0 | AD7: =SUM(AB7:AC7) -> 101316.72
A8: =_xlfn.XLOOKUP(B8*1,'Reference '!I:I,'Reference '!K:K) -> Ben Gbeve | B8: =LEFT(C8,3) -> 601 | C8: 601_IS Service Delivery_EIL_GBP | D8: 601_IS Service Delivery_EIL_GBP | E8: 307200 - Training | F8: 307200 - Training | G8: 000000_Default | H8: 000000_Default | I8: 0000_Default | J8: 0000_Default | K8: Training | L8: Various | M8: Budget 2026 | N8: GBP | O8: 1000 | P8: 1000 | Q8: 1000 | R8: 1000 | S8: 1000 | T8: 1000 | U8: 1000 | V8: 1000 | W8: 1000 | X8: 1000 | Y8: 1000 | Z8: 1000 | AA8: 12000 | AB8: =IF(N8="EUR",AA8,IF(N8="GBP",AA8/Rate!$C$3,AA8/Rate!$C$5)) -> 13793.103 | AC8: =IFERROR(VLOOKUP(K8,'4.2 Simplify Savings'!K:AB,18,0),0) -> 0 | AD8: =SUM(AB8:AC8) -> 13793.103
A9: =_xlfn.XLOOKUP(B9*1,'Reference '!I:I,'Reference '!K:K) -> Xavier Romanet | B9: =LEFT(C9,3) -> 605 | C9: 605_IS Sales System_EIL_GBP | D9: 605_IS Sales System_EIL_GBP | E9: 307200 - Training | F9: 307200 - Training | G9: 000000_Default | H9: 000000_Default | I9: 0000_Default | J9: 0000_Default | K9: Training budget for increased team-wide knowledge | L9: Various | M9: 5+7 2024 & Budget 25 | N9: GBP | Y9: 833 | Z9: 833 | AA9: 1666 | AB9: =IF(N9="EUR",AA9,IF(N9="GBP",AA9/Rate!$C$3,AA9/Rate!$C$5)) -> 1914.9425 | AC9: =IFERROR(VLOOKUP(K9,'4.2 Simplify Savings'!K:AB,18,0),0) -> 0 | AD9: =SUM(AB9:AC9) -> 1914.9425
A10: =_xlfn.XLOOKUP(B10*1,'Reference '!I:I,'Reference '!K:K) -> Ben Gbeve | B10: =LEFT(C10,3) -> 601 | C10: 601_IS Service Delivery_EIL_GBP | D10: 601_IS Service Delivery_EIL_GBP | E10: 340001 - Local Area Network (LAN) | F10: 340001 - Local Area Network (LAN) | G10: 000000_Default | H10: 000000_Default | I10: 0000_Default | J10: 0000_Default | K10: SPI Terminal Wi-Fi | L10: WIFI METROPOLIS BV | M10: Budget 2026 | N10: GBP | O10: 2175 | P10: 2175 | Q10: 2175 | R10: 2175 | S10: 2175 | T10: 2175 | U10: 2175 | V10: 2175 | W10: 2175 | X10: 2175 | Y10: 2175 | Z10: 2175 | AA10: 26100 | AB10: =IF(N10="EUR",AA10,IF(N10="GBP",AA10/Rate!$C$3,AA10/Rate!$C$5)) -> 30000 | AC10: =IFERROR(VLOOKUP(K10,'4.2 Simplify Savings'!K:AB,18,0),0) -> 0 | AD10: =SUM(AB10:AC10) -> 30000
A11: =_xlfn.XLOOKUP(B11*1,'Reference '!I:I,'Reference '!K:K) -> Ben Gbeve | B11: =LEFT(C11,3) -> 601 | C11: 601_IS Service Delivery_EIL_GBP | D11: 601_IS Service Delivery_EIL_GBP | E11: 340001 - Local Area Network (LAN) | F11: 340001 - Local Area Network (LAN) | G11: 000000_Default | H11: 000000_Default | I11: 0000_Default | J11: 0000_Default | K11: New Amsterdam Terminal Wi-Fi | L11: Natilik | M11: Budget 2026 | N11: GBP | O11: 670 | P11: 670 | Q11: 670 | R11: 670 | S11: 670 | T11: 670 | U11: 670 | V11: 670 | W11: 670 | X11: 670 | Y11: 670 | Z11: 670 | AA11: 8040 | AB11: =IF(N11="EUR",AA11,IF(N11="GBP",AA11/Rate!$C$3,AA11/Rate!$C$5)) -> 9241.3793 | AC11: =IFERROR(VLOOKUP(K11,'4.2 Simplify Savings'!K:AB,18,0),0) -> 0 | AD11: =SUM(AB11:AC11) -> 9241.3793
A12: =_xlfn.XLOOKUP(B12*1,'Reference '!I:I,'Reference '!K:K) -> Ben Gbeve | B12: =LEFT(C12,3) -> 601 | C12: 601_IS Service Delivery_EIL_GBP | D12: 601_IS Service Delivery_EIL_GBP | E12: 340001 - Local Area Network (LAN) | F12: 340001 - Local Area Network (LAN) | G12: 000000_Default | H12: 000000_Default | I12: 0000_Default | J12: 0000_Default | K12: Network swtiches at all locations | L12: Meraki and Others | M12: Budget 2026 | N12: GBP | O12: 6350 | P12: 6350 | Q12: 6350 | R12: 6350 | S12: 6350 | T12: 6350 | U12: 6350 | V12: 6350 | W12: 6350 | X12: 6350 | Y12: 6350 | Z12: 6350 | AA12: 76200 | AB12: =IF(N12="EUR",AA12,IF(N12="GBP",AA12/Rate!$C$3,AA12/Rate!$C$5)) -> 87586.207 | AC12: =IFERROR(VLOOKUP(K12,'4.2 Simplify Savings'!K:AB,18,0),0) -> 0 | AD12: =SUM(AB12:AC12) -> 87586.207
A13: =_xlfn.XLOOKUP(B13*1,'Reference '!I:I,'Reference '!K:K) -> Ben Gbeve | B13: =LEFT(C13,3) -> 601 | C13: 601_IS Service Delivery_EIL_GBP | D13: 601_IS Service Delivery_EIL_GBP | E13: 340001 - Local Area Network (LAN) | F13: 340001 - Local Area Network (LAN) | G13: 000000_Default | H13: 000000_Default | I13: 0000_Default | J13: 0000_Default | K13: Firewall including Phsical/Cloud Palo Alto Support | L13: BYTES | M13: Budget 2026 | N13: GBP | O13: 6917 | P13: 6917 | Q13: 6917 | R13: 6917 | S13: 6917 | T13: 6917 | U13: 6917 | V13: 6917 | W13: 6917 | X13: 6917 | Y13: 6917 | Z13: 6917 | AA13: 83004 | AB13: =IF(N13="EUR",AA13,IF(N13="GBP",AA13/Rate!$C$3,AA13/Rate!$C$5)) -> 95406.897 | AC13: =IFERROR(VLOOKUP(K13,'4.2 Simplify Savings'!K:AB,18,0),0) -> -40860 | AD13: =SUM(AB13:AC13) -> 54546.897
A14: =_xlfn.XLOOKUP(B14*1,'Reference '!I:I,'Reference '!K:K) -> Ben Gbeve | B14: =LEFT(C14,3) -> 601 | C14: 601_IS Service Delivery_EIL_GBP | D14: 601_IS Service Delivery_EIL_GBP | E14: 340001 - Local Area Network (LAN) | F14: 340001 - Local Area Network (LAN) | G14: 000000_Default | H14: 000000_Default | I14: 0000_Default | J14: 0000_Default | K14: ClearPass Wi-Fi Controllers & Aruba - Now replaced by licences for Cisco ISE | L14: ASP | M14: Budget 2026 | N14: GBP | O14: 4000 | P14: 4000 | Q14: 4000 | R14: 4000 | S14: 4000 | T14: 4000 | U14: 4000 | V14: 4000 | W14: 4000 | X14: 4000 | Y14: 4000 | Z14: 4000 | AA14: 48000 | AB14: =IF(N14="EUR",AA14,IF(N14="GBP",AA14/Rate!$C$3,AA14/Rate!$C$5)) -> 55172.414 | AC14: =IFERROR(VLOOKUP(K14,'4.2 Simplify Savings'!K:AB,18,0),0) -> -27240 | AD14: =SUM(AB14:AC14) -> 27932.414
A15: =_xlfn.XLOOKUP(B15*1,'Reference '!I:I,'Reference '!K:K) -> Ben Gbeve | B15: =LEFT(C15,3) -> 601 | C15: 601_IS Service Delivery_EIL_GBP | D15: 601_IS Service Delivery_EIL_GBP | E15: 340100 - Communication rooms | F15: 340100 - Communication rooms | G15: 000000_Default | H15: 000000_Default | I15: 0000_Default | J15: 0000_Default | K15: Provision to maitain comms rooms (UPS, disposals, etc) | L15: SECURE POWER / Others | M15: Budget 2026 | N15: GBP | O15: 2500 | P15: 2500 | Q15: 2500 | R15: 2500 | S15: 2500 | T15: 2500 | U15: 2500 | V15: 2500 | W15: 2500 | X15: 2500 | Y15: 2500 | Z15: 2500 | AA15: 30000 | AB15: =IF(N15="EUR",AA15,IF(N15="GBP",AA15/Rate!$C$3,AA15/Rate!$C$5)) -> 34482.759 | AC15: =IFERROR(VLOOKUP(K15,'4.2 Simplify Savings'!K:AB,18,0),0) -> 0 | AD15: =SUM(AB15:AC15) -> 34482.759
A16: =_xlfn.XLOOKUP(B16*1,'Reference '!I:I,'Reference '!K:K) -> Ben Gbeve | B16: =LEFT(C16,3) -> 601 | C16: 601_IS Service Delivery_EIL_GBP | D16: 601_IS Service Delivery_EIL_GBP | E16: 340200 - Computer / NIIT | F16: 340200 - Computer / NIIT | G16: 000000_Default | H16: 000000_Default | I16: 0000_Default | J16: 0000_Default | K16: Managed Service Provider - Amsterdam Coverage | L16: HEXAWARE | M16: Budget 2026 | N16: GBP | O16: 5416.67 | P16: 5416.67 | Q16: 5416.67 | R16: 5416.67 | S16: 5416.67 | T16: 5416.67 | U16: 5416.67 | V16: 5416.67 | W16: 5416.67 | X16: 5416.67 | Y16: 5416.67 | Z16: 5416.67 | AA16: 65000.04 | AB16: =IF(N16="EUR",AA16,IF(N16="GBP",AA16/Rate!$C$3,AA16/Rate!$C$5)) -> 74712.69 | AC16: =IFERROR(VLOOKUP(K16,'4.2 Simplify Savings'!K:AB,18,0),0) -> 0 | AD16: =SUM(AB16:AC16) -> 74712.69
A17: =_xlfn.XLOOKUP(B17*1,'Reference '!I:I,'Reference '!K:K) -> Ben Gbeve | B17: =LEFT(C17,3) -> 601 | C17: 601_IS Service Delivery_EIL_GBP | D17: 601_IS Service Delivery_EIL_GBP | E17: 340200 - Computer / NIIT | F17: 340200 - Computer / NIIT | G17: 000000_Default | H17: 000000_Default | I17: 0000_Default | J17: 0000_Default | K17: Managed Service Provider - Arc/Rcs variations | L17: HEXAWARE | M17: Budget 2026 | N17: GBP | O17: 8333.33 | P17: 8333.33 | Q17: 8333.33 | R17: 8333.33 | S17: 8333.33 | T17: 8333.33 | U17: 8333.33 | V17: 8333.33 | W17: 8333.33 | X17: 8333.33 | Y17: 8333.33 | Z17: 8333.33 | AA17: 99999.96 | AB17: =IF(N17="EUR",AA17,IF(N17="GBP",AA17/Rate!$C$3,AA17/Rate!$C$5)) -> 114942.48 | AC17: =IFERROR(VLOOKUP(K17,'4.2 Simplify Savings'!K:AB,18,0),0) -> 0 | AD17: =SUM(AB17:AC17) -> 114942.48
A18: =_xlfn.XLOOKUP(B18*1,'Reference '!I:I,'Reference '!K:K) -> Ben Gbeve | B18: =LEFT(C18,3) -> 601 | C18: 601_IS Service Delivery_EIL_GBP | D18: 601_IS Service Delivery_EIL_GBP | E18: 340200 - Computer / NIIT | F18: 340200 - Computer / NIIT | G18: 000000_Default | H18: 000000_Default | I18: 0000_Default | J18: 0000_Default | K18: Managed Service Provider - Core Service Charge (BAU & Tx) | L18: HEXAWARE | M18: Budget 2026 | N18: GBP | O18: 149382 | P18: 149382 | Q18: 149382 | R18: 149382 | S18: 149382 | T18: 149382 | U18: 149382 | V18: 149382 | W18: 149382 | X18: 149382 | Y18: 149382 | Z18: 149382 | AA18: 1792584 | AB18: =IF(N18="EUR",AA18,IF(N18="GBP",AA18/Rate!$C$3,AA18/Rate!$C$5)) -> 2060441.4 | AC18: ='4.2 Simplify Savings'!$AB$5 -> -135757.32 | AD18: =SUM(AB18:AC18) -> 1924684.1
A19: =_xlfn.XLOOKUP(B19*1,'Reference '!I:I,'Reference '!K:K) -> Ben Gbeve | B19: =LEFT(C19,3) -> 601 | C19: 601_IS Service Delivery_EIL_GBP | D19: 601_IS Service Delivery_EIL_GBP | E19: 340200 - Computer / NIIT | F19: 340200 - Computer / NIIT | G19: 000000_Default | H19: 000000_Default | I19: 0000_Default | J19: 0000_Default | K19: Managed Service Provider - Non BAU | L19: HEXAWARE | M19: Budget 2026 | N19: GBP | O19: 11250 | P19: 11250 | Q19: 11250 | R19: 11250 | S19: 11250 | T19: 11250 | U19: 11250 | V19: 11250 | W19: 11250 | X19: 11250 | Y19: 11250 | Z19: 11250 | AA19: 135000 | AB19: =IF(N19="EUR",AA19,IF(N19="GBP",AA19/Rate!$C$3,AA19/Rate!$C$5)) -> 155172.41 | AC19: =IFERROR(VLOOKUP(K19,'4.2 Simplify Savings'!K:AB,18,0),0) -> 0 | AD19: =SUM(AB19:AC19) -> 155172.41
A20: =_xlfn.XLOOKUP(B20*1,'Reference '!I:I,'Reference '!K:K) -> Ben Gbeve | B20: =LEFT(C20,3) -> 601 | C20: 601_IS Service Delivery_EIL_GBP | D20: 601_IS Service Delivery_EIL_GBP | E20: 340200 - Computer / NIIT | F20: 340200 - Computer / NIIT | G20: 000000_Default | H20: 000000_Default | I20: 0000_Default | J20: 0000_Default | K20: Managed Service Provider - TUPE Provision | L20: HEXAWARE | M20: Budget 2026 | N20: GBP | O20: 7900 | P20: 7900 | Q20: 7900 | R20: 7900 | S20: 7900 | T20: 7900 | U20: 7900 | V20: 7900 | W20: 7900 | X20: 7900 | Y20: 7900 | Z20: 7900 | AA20: 94800 | AB20: =IF(N20="EUR",AA20,IF(N20="GBP",AA20/Rate!$C$3,AA20/Rate!$C$5)) -> 108965.52 | AC20: =IFERROR(VLOOKUP(K20,'4.2 Simplify Savings'!K:AB,18,0),0) -> 0 | AD20: =SUM(AB20:AC20) -> 108965.52
A21: =_xlfn.XLOOKUP(B21*1,'Reference '!I:I,'Reference '!K:K) -> Ben Gbeve | B21: =LEFT(C21,3) -> 601 | C21: 601_IS Service Delivery_EIL_GBP | D21: 601_IS Service Delivery_EIL_GBP | E21: 340200 - Computer / NIIT | F21: 340200 - Computer / NIIT | G21: 000000_Default | H21: 000000_Default | I21: 0000_Default | J21: 0000_Default | K21: Managed Service Provider - Application Support | L21: COFORGE U.K. LIMITED- | M21: Budget 2026 | N21: GBP | O21: 2900 | P21: 2900 | Q21: 2900 | R21: 2900 | S21: 2900 | T21: 2900 | U21: 2900 | V21: 2900 | W21: 2900 | X21: 2900 | Y21: 2900 | Z21: 2900 | AA21: 34800 | AB21: =IF(N21="EUR",AA21,IF(N21="GBP",AA21/Rate!$C$3,AA21/Rate!$C$5)) -> 40000 | AC21: =IFERROR(VLOOKUP(K21,'4.2 Simplify Savings'!K:AB,18,0),0) -> 0 | AD21: =SUM(AB21:AC21) -> 40000
A22: =_xlfn.XLOOKUP(B22*1,'Reference '!I:I,'Reference '!K:K) -> Ben Gbeve | B22: =LEFT(C22,3) -> 601 | C22: 601_IS Service Delivery_EIL_GBP | D22: 601_IS Service Delivery_EIL_GBP | E22: 340300 - IS consumables | F22: 340300 - IS consumables | G22: 000000_Default | H22: 000000_Default | I22: 0000_Default | J22: 0000_Default | K22: Hardware and consumables | L22: Various | M22: Budget 2026 | N22: GBP | O22: 9000 | P22: 9000 | Q22: 9000 | R22: 9000 | S22: 9000 | T22: 9000 | U22: 9000 | V22: 9000 | W22: 9000 | X22: 9000 | Y22: 9000 | Z22: 9000 | AA22: 108000 | AB22: =IF(N22="EUR",AA22,IF(N22="GBP",AA22/Rate!$C$3,AA22/Rate!$C$5)) -> 124137.93 | AC22: =IFERROR(VLOOKUP(K22,'4.2 Simplify Savings'!K:AB,18,0),0) -> 0 | AD22: =SUM(AB22:AC22) -> 124137.93
A23: =_xlfn.XLOOKUP(B23*1,'Reference '!I:I,'Reference '!K:K) -> Ben Gbeve | B23: =LEFT(C23,3) -> 601 | C23: 601_IS Service Delivery_EIL_GBP | D23: 601_IS Service Delivery_EIL_GBP | E23: 340400 - IS Hardware maintenance & support | F23: 340400 - IS Hardware maintenance & support | G23: 000000_Default | H23: 000000_Default | I23: 0000_Default | J23: 0000_Default | K23: Call out & repair of display / meeting room systems | L23: SOLUTIONS AUDIO VISUAL LIMITED | M23: Budget 2026 | N23: GBP | O23: 3230 | P23: 3230 | Q23: 3230 | R23: 3230 | S23: 3230 | T23: 3230 | U23: 3230 | V23: 3230 | W23: 3230 | X23: 3230 | Y23: 3230 | Z23: 3230 | AA23: 38760 | AB23: =IF(N23="EUR",AA23,IF(N23="GBP",AA23/Rate!$C$3,AA23/Rate!$C$5)) -> 44551.724 | AC23: =IFERROR(VLOOKUP(K23,'4.2 Simplify Savings'!K:AB,18,0),0) -> 0 | AD23: =SUM(AB23:AC23) -> 44551.724
A24: =_xlfn.XLOOKUP(B24*1,'Reference '!I:I,'Reference '!K:K) -> Ben Gbeve | B24: =LEFT(C24,3) -> 601 | C24: 601_IS Service Delivery_EIL_GBP | D24: 601_IS Service Delivery_EIL_GBP | E24: 340400 - IS Hardware maintenance & support | F24: 340400 - IS Hardware maintenance & support | G24: 000000_Default | H24: 000000_Default | I24: 0000_Default | J24: 0000_Default | K24: Stand alone printer | L24: Printer Support | M24: Budget 2026 | N24: GBP | O24: 495.42 | P24: 495.42 | Q24: 495.42 | R24: 495.42 | S24: 495.42 | T24: 495.42 | U24: 495.42 | V24: 495.42 | W24: 495.42 | X24: 495.42 | Y24: 495.42 | Z24: 495.42 | AA24: 5945.04 | AB24: =IF(N24="EUR",AA24,IF(N24="GBP",AA24/Rate!$C$3,AA24/Rate!$C$5)) -> 6833.3793 | AC24: =IFERROR(VLOOKUP(K24,'4.2 Simplify Savings'!K:AB,18,0),0) -> 0 | AD24: =SUM(AB24:AC24) -> 6833.3793
A25: =_xlfn.XLOOKUP(B25*1,'Reference '!I:I,'Reference '!K:K) -> Ben Gbeve | B25: =LEFT(C25,3) -> 601 | C25: 601_IS Service Delivery_EIL_GBP | D25: 601_IS Service Delivery_EIL_GBP | E25: 340400 - IS Hardware maintenance & support | F25: 340400 - IS Hardware maintenance & support | G25: 000000_Default | H25: 000000_Default | I25: 0000_Default | J25: 0000_Default | K25: Teleohony at TMI (Siemens PBX) | L25: ELITETELE.COM PLC T/A ELITE GROUP | M25: Budget 2026 | N25: GBP | O25: 583.33 | P25: 583.33 | Q25: 583.33 | R25: 583.33 | S25: 583.33 | T25: 583.33 | U25: 583.33 | V25: 583.33 | W25: 583.33 | X25: 583.33 | Y25: 583.33 | Z25: 583.33 | AA25: 6999.96 | AB25: =IF(N25="EUR",AA25,IF(N25="GBP",AA25/Rate!$C$3,AA25/Rate!$C$5)) -> 8045.931 | AC25: =IFERROR(VLOOKUP(K25,'4.2 Simplify Savings'!K:AB,18,0),0) -> 0 | AD25: =SUM(AB25:AC25) -> 8045.931
A26: =_xlfn.XLOOKUP(B26*1,'Reference '!I:I,'Reference '!K:K) -> Ben Gbeve | B26: =LEFT(C26,3) -> 601 | C26: 601_IS Service Delivery_EIL_GBP | D26: 601_IS Service Delivery_EIL_GBP | E26: 340400 - IS Hardware maintenance & support | F26: 340400 - IS Hardware maintenance & support | G26: 000000_Default | H26: 000000_Default | I26: 0000_Default | J26: 0000_Default | K26: SST Payement Devices at stations | L26: ADYEN N.V | M26: Budget 2026 | N26: GBP | O26: 436 | P26: 436 | Q26: 436 | R26: 436 | S26: 436 | T26: 436 | U26: 436 | V26: 436 | W26: 436 | X26: 436 | Y26: 436 | Z26: 436 | AA26: 5232 | AB26: =IF(N26="EUR",AA26,IF(N26="GBP",AA26/Rate!$C$3,AA26/Rate!$C$5)) -> 6013.7931 | AC26: =IFERROR(VLOOKUP(K26,'4.2 Simplify Savings'!K:AB,18,0),0) -> 0 | AD26: =SUM(AB26:AC26) -> 6013.7931
A27: =_xlfn.XLOOKUP(B27*1,'Reference '!I:I,'Reference '!K:K) -> Mael Delmas | B27: =LEFT(C27,3) -> 604 | C27: 604_IS Customer Systems_EIL_GBP | D27: 604_IS Customer Systems_EIL_GBP | E27: 340400 - IS Hardware maintenance & support | F27: 340400 - IS Hardware maintenance & support | G27: 000000_Default | H27: 000000_Default | I27: 0000_Default | J27: 0000_Default | K27: [Stations] - Borders - SAS Parafe - maintenance | L27: Thales | M27: Budget 2026 | N27: GBP | O27: 13000 | P27: 13000 | Q27: 13000 | R27: 13000 | S27: 13000 | T27: 13000 | U27: 13000 | V27: 13000 | W27: 13000 | X27: 13000 | Y27: 13000 | Z27: 13000 | AA27: 156000 | AB27: =IF(N27="EUR",AA27,IF(N27="GBP",AA27/Rate!$C$3,AA27/Rate!$C$5)) -> 179310.34 | AC27: =IFERROR(VLOOKUP(K27,'4.2 Simplify Savings'!K:AB,18,0),0) -> 0 | AD27: =SUM(AB27:AC27) -> 179310.34
A28: =_xlfn.XLOOKUP(B28*1,'Reference '!I:I,'Reference '!K:K) -> Mael Delmas | B28: =LEFT(C28,3) -> 604 | C28: 604_IS Customer Systems_EIL_GBP | D28: 604_IS Customer Systems_EIL_GBP | E28: 340400 - IS Hardware maintenance & support | F28: 340400 - IS Hardware maintenance & support | G28: 000000_Default | H28: 000000_Default | I28: 0000_Default | J28: 0000_Default | K28: [Stations] - Ticket Gates maintenance | L28: IER/EASIER | M28: Budget 2026 | N28: GBP | O28: 2600 | P28: 2600 | Q28: 2600 | R28: 2600 | S28: 2600 | T28: 2600 | U28: 2600 | V28: 2600 | W28: 2600 | X28: 2600 | Y28: 2600 | Z28: 2600 | AA28: 31200 | AB28: =IF(N28="EUR",AA28,IF(N28="GBP",AA28/Rate!$C$3,AA28/Rate!$C$5)) -> 35862.069 | AC28: =IFERROR(VLOOKUP(K28,'4.2 Simplify Savings'!K:AB,18,0),0) -> 0 | AD28: =SUM(AB28:AC28) -> 35862.069
A29: =_xlfn.XLOOKUP(B29*1,'Reference '!I:I,'Reference '!K:K) -> Ben Gbeve | B29: =LEFT(C29,3) -> 601 | C29: 601_IS Service Delivery_EIL_EUR | D29: 601_IS Service Delivery_EIL_EUR | E29: 341001 - Global Wide Area Network (GWAN) | F29: 341001 - Global Wide Area Network (GWAN) | G29: 000000_Default | H29: 000000_Default | I29: 0000_Default | J29: 0000_Default | K29: Connection to Tigre for TMI dedicated PCs | L29: HERMES INFORMATION TECHNOLOGY RAIL (HIT RAIL) BV | M29: Budget 2026 | N29: EUR | O29: 4356.25 | P29: 4356.25 | Q29: 4356.25 | R29: 4356.25 | S29: 4356.25 | T29: 4356.25 | U29: 4356.25 | V29: 4356.25 | W29: 4356.25 | X29: 4356.25 | Y29: 4356.25 | Z29: 4356.25 | AA29: 52275 | AB29: =IF(N29="EUR",AA29,IF(N29="GBP",AA29/Rate!$C$3,AA29/Rate!$C$5)) -> 52275 | AC29: =IFERROR(VLOOKUP(K29,'4.2 Simplify Savings'!K:AB,18,0),0) -> 0 | AD29: =SUM(AB29:AC29) -> 52275
A30: =_xlfn.XLOOKUP(B30*1,'Reference '!I:I,'Reference '!K:K) -> Ben Gbeve | B30: =LEFT(C30,3) -> 601 | C30: 601_IS Service Delivery_EIL_GBP | D30: 601_IS Service Delivery_EIL_GBP | E30: 341001 - Global Wide Area Network (GWAN) | F30: 341001 - Global Wide Area Network (GWAN) | G30: 000000_Default | H30: 000000_Default | I30: 0000_Default | J30: 0000_Default | K30: EIL MPLS WAN & Internet Connections | L30: MASERGY COMMUNICATIONS INC | M30: Budget 2026 | N30: GBP | O30: 48085 | P30: 48085 | Q30: 48085 | R30: 48085 | S30: 48085 | T30: 48085 | U30: 48085 | V30: 48085 | W30: 48085 | X30: 48085 | Y30: 48085 | Z30: 48085 | AA30: 577020 | AB30: =IF(N30="EUR",AA30,IF(N30="GBP",AA30/Rate!$C$3,AA30/Rate!$C$5)) -> 663241.38 | AC30: =IFERROR(VLOOKUP(K30,'4.2 Simplify Savings'!K:AB,18,0),0) -> -289425 | AD30: =SUM(AB30:AC30) -> 373816.38
A31: =_xlfn.XLOOKUP(B31*1,'Reference '!I:I,'Reference '!K:K) -> Ben Gbeve | B31: =LEFT(C31,3) -> 601 | C31: 601_IS Service Delivery_EIL_USD | D31: 601_IS Service Delivery_EIL_USD | E31: 341001 - Global Wide Area Network (GWAN) | F31: 341001 - Global Wide Area Network (GWAN) | G31: 000000_Default | H31: 000000_Default | I31: 0000_Default | J31: 0000_Default | K31: SASE Replacement for Masergy MPLS and Security | L31: CATO NETWORKS (Or A N OTHER) | M31: Budget 2026 | N31: USD | R31: 35000 | S31: 35000 | T31: 35000 | U31: 35000 | V31: 35000 | W31: 35000 | X31: 35000 | Y31: 35000 | Z31: 35000 | AA31: 315000 | AB31: =IF(N31="EUR",AA31,IF(N31="GBP",AA31/Rate!$C$3,AA31/Rate!$C$5)) -> 269230.77 | AC31: =IFERROR(VLOOKUP(K31,'4.2 Simplify Savings'!K:AB,18,0),0) -> 0 | AD31: =SUM(AB31:AC31) -> 269230.77
A32: =_xlfn.XLOOKUP(B32*1,'Reference '!I:I,'Reference '!K:K) -> Ben Gbeve | B32: =LEFT(C32,3) -> 601 | C32: 601_IS Service Delivery_EIL_EUR | D32: 601_IS Service Delivery_EIL_EUR | E32: 341100 - Non Global Wide Area Network (GWAN) | F32: 341100 - Non Global Wide Area Network (GWAN) | G32: 000000_Default | H32: 000000_Default | I32: 0000_Default | J32: 0000_Default | K32: Internet in BMI BL Lounge | L32: EUROFIBER N.V. | M32: Budget 2026 | N32: EUR | O32: 385 | P32: 385 | Q32: 385 | R32: 385 | S32: 385 | T32: 385 | U32: 385 | V32: 385 | W32: 385 | X32: 385 | Y32: 385 | Z32: 385 | AA32: 4620 | AB32: =IF(N32="EUR",AA32,IF(N32="GBP",AA32/Rate!$C$3,AA32/Rate!$C$5)) -> 4620 | AC32: =IFERROR(VLOOKUP(K32,'4.2 Simplify Savings'!K:AB,18,0),0) -> -2310 | AD32: =SUM(AB32:AC32) -> 2310
A33: =_xlfn.XLOOKUP(B33*1,'Reference '!I:I,'Reference '!K:K) -> Ben Gbeve | B33: =LEFT(C33,3) -> 601 | C33: 601_IS Service Delivery_EIL_GBP | D33: 601_IS Service Delivery_EIL_GBP | E33: 341100 - Non Global Wide Area Network (GWAN) | F33: 341100 - Non Global Wide Area Network (GWAN) | G33: 000000_Default | H33: 000000_Default | I33: 0000_Default | J33: 0000_Default | K33: Amsterdam Station Internet Access (3yr contract from Dec 2023) | L33: BT BUSINESS COMMUNICATIONS | M33: Budget 2026 | N33: GBP | O33: 3470 | P33: 3470 | Q33: 3470 | R33: 3470 | S33: 3470 | T33: 3470 | U33: 3470 | V33: 3470 | W33: 3470 | X33: 3470 | Y33: 3470 | Z33: 3470 | AA33: 41640 | AB33: =IF(N33="EUR",AA33,IF(N33="GBP",AA33/Rate!$C$3,AA33/Rate!$C$5)) -> 47862.069 | AC33: =IFERROR(VLOOKUP(K33,'4.2 Simplify Savings'!K:AB,18,0),0) -> 0 | AD33: =SUM(AB33:AC33) -> 47862.069
A34: =_xlfn.XLOOKUP(B34*1,'Reference '!I:I,'Reference '!K:K) -> Ben Gbeve | B34: =LEFT(C34,3) -> 601 | C34: 601_IS Service Delivery_EIL_GBP | D34: 601_IS Service Delivery_EIL_GBP | E34: 341100 - Non Global Wide Area Network (GWAN) | F34: 341100 - Non Global Wide Area Network (GWAN) | G34: 000000_Default | H34: 000000_Default | I34: 0000_Default | J34: 0000_Default | K34: Rotterdam Station Internat Access (3yr contract from Oct 2020) | L34: BT BUSINESS COMMUNICATIONS | M34: Budget 2026 | N34: GBP | O34: 930 | P34: 930 | Q34: 930 | R34: 930 | S34: 930 | T34: 930 | U34: 930 | V34: 930 | W34: 930 | X34: 930 | Y34: 930 | Z34: 930 | AA34: 11160 | AB34: =IF(N34="EUR",AA34,IF(N34="GBP",AA34/Rate!$C$3,AA34/Rate!$C$5)) -> 12827.586 | AC34: =IFERROR(VLOOKUP(K34,'4.2 Simplify Savings'!K:AB,18,0),0) -> -9499.95 | AD34: =SUM(AB34:AC34) -> 3327.6362
A35: =_xlfn.XLOOKUP(B35*1,'Reference '!I:I,'Reference '!K:K) -> Ben Gbeve | B35: =LEFT(C35,3) -> 601 | C35: 601_IS Service Delivery_EIL_EUR | D35: 601_IS Service Delivery_EIL_EUR | E35: 341200 - Internet access | F35: 341200 - Internet access | G35: 000000_Default | H35: 000000_Default | I35: 1373_WiFi On Board | J35: 1373_WiFi On Board | K35: M2M Energy Monitoring | L35: ORANGE SA | M35: Budget 2026 | N35: EUR | O35: 617 | P35: 617 | Q35: 617 | R35: 617 | S35: 617 | T35: 617 | U35: 617 | V35: 617 | W35: 617 | X35: 617 | Y35: 617 | Z35: 617 | AA35: 7404 | AB35: =IF(N35="EUR",AA35,IF(N35="GBP",AA35/Rate!$C$3,AA35/Rate!$C$5)) -> 7404 | AC35: =IFERROR(VLOOKUP(K35,'4.2 Simplify Savings'!K:AB,18,0),0) -> 0 | AD35: =SUM(AB35:AC35) -> 7404
A36: =_xlfn.XLOOKUP(B36*1,'Reference '!I:I,'Reference '!K:K) -> Ben Gbeve | B36: =LEFT(C36,3) -> 601 | C36: 601_IS Service Delivery_EIL_EUR | D36: 601_IS Service Delivery_EIL_EUR | E36: 341200 - Internet access | F36: 341200 - Internet access | G36: 000000_Default | H36: 000000_Default | I36: 1373_WiFi On Board | J36: 1373_WiFi On Board | K36: Onboard passanger Wi-Fi (Channel EIL) | L36: ORANGE | M36: Budget 2026 | N36: EUR | O36: 145537 | P36: 145537 | Q36: 145537 | R36: 145537 | S36: 145537 | T36: 145537 | U36: 145537 | V36: 145537 | W36: 145537 | X36: 145537 | Y36: 145537 | Z36: 145537 | AA36: 1746444 | AB36: =IF(N36="EUR",AA36,IF(N36="GBP",AA36/Rate!$C$3,AA36/Rate!$C$5)) -> 1746444 | AC36: =IFERROR(VLOOKUP(K36,'4.2 Simplify Savings'!K:AB,18,0),0) -> -246444 | AD36: =SUM(AB36:AC36) -> 1500000
A37: =_xlfn.XLOOKUP(B37*1,'Reference '!I:I,'Reference '!K:K) -> Ben Gbeve | B37: =LEFT(C37,3) -> 601 | C37: 601_IS Service Delivery_EIL_GBP | D37: 601_IS Service Delivery_EIL_GBP | E37: 341200 - Internet access | F37: 341200 - Internet access | G37: 000000_Default | H37: 000000_Default | I37: 0000_Default | J37: 0000_Default | K37: Internet in PNO BL Lounge | L37: TELSTRA EUROPE LTD | M37: Budget 2026 | N37: GBP | O37: 2768 | P37: 2768 | Q37: 2768 | R37: 2768 | S37: 2768 | T37: 2768 | U37: 2768 | V37: 2768 | W37: 2768 | X37: 2768 | Y37: 2768 | Z37: 2768 | AA37: 33216 | AB37: =IF(N37="EUR",AA37,IF(N37="GBP",AA37/Rate!$C$3,AA37/Rate!$C$5)) -> 38179.31 | AC37: =IFERROR(VLOOKUP(K37,'4.2 Simplify Savings'!K:AB,18,0),0) -> -28275.12 | AD37: =SUM(AB37:AC37) -> 9904.1903
A38: =_xlfn.XLOOKUP(B38*1,'Reference '!I:I,'Reference '!K:K) -> Ben Gbeve | B38: =LEFT(C38,3) -> 601 | C38: 601_IS Service Delivery_EIL_GBP | D38: 601_IS Service Delivery_EIL_GBP | E38: 341200 - Internet access | F38: 341200 - Internet access | G38: 000000_Default | H38: 000000_Default | I38: 1373_WiFi On Board | J38: 1373_WiFi On Board | K38: M2M/CSD Jasper 2G train systems monitoring (No PIS contract) | L38: TELEFONICA UK LIMITED | M38: Budget 2026 | N38: GBP | O38: 5416.67 | P38: 5416.67 | Q38: 5416.67 | R38: 5416.67 | S38: 5416.67 | T38: 5416.67 | U38: 5416.67 | V38: 5416.67 | W38: 5416.67 | X38: 5416.67 | Y38: 5416.67 | Z38: 5416.67 | AA38: 65000.04 | AB38: =IF(N38="EUR",AA38,IF(N38="GBP",AA38/Rate!$C$3,AA38/Rate!$C$5)) -> 74712.69 | AC38: =IFERROR(VLOOKUP(K38,'4.2 Simplify Savings'!K:AB,18,0),0) -> 0 | AD38: =SUM(AB38:AC38) -> 74712.69
A39: =_xlfn.XLOOKUP(B39*1,'Reference '!I:I,'Reference '!K:K) -> Ben Gbeve | B39: =LEFT(C39,3) -> 601 | C39: 601_IS Service Delivery_EIL_GBP | D39: 601_IS Service Delivery_EIL_GBP | E39: 342001 - Systems support | F39: 342001 - Systems support | G39: 000000_Default | H39: 000000_Default | I39: 0000_Default | J39: 0000_Default | K39: WISI Mobile screens at stations | L39: Met Systems Limited | M39: Budget 2026 | N39: GBP | O39: 3750 | P39: 3750 | Q39: 3750 | R39: 3750 | S39: 3750 | T39: 3750 | U39: 3750 | V39: 3750 | W39: 3750 | X39: 3750 | Y39: 3750 | Z39: 3750 | AA39: 45000 | AB39: =IF(N39="EUR",AA39,IF(N39="GBP",AA39/Rate!$C$3,AA39/Rate!$C$5)) -> 51724.138 | AC39: =IFERROR(VLOOKUP(K39,'4.2 Simplify Savings'!K:AB,18,0),0) -> 0 | AD39: =SUM(AB39:AC39) -> 51724.138
A40: =_xlfn.XLOOKUP(B40*1,'Reference '!I:I,'Reference '!K:K) -> Ben Gbeve | B40: =LEFT(C40,3) -> 601 | C40: 601_IS Service Delivery_EIL_GBP | D40: 601_IS Service Delivery_EIL_GBP | E40: 342001 - Systems support | F40: 342001 - Systems support | G40: 000000_Default | H40: 000000_Default | I40: 0000_Default | J40: 0000_Default | K40: Support for station display screens | L40: MAINT-TEK ELECTRONICS SERVICES | M40: Budget 2026 | N40: GBP | O40: 7708.33 | P40: 7708.33 | Q40: 7708.33 | R40: 7708.33 | S40: 7708.33 | T40: 7708.33 | U40: 7708.33 | V40: 7708.33 | W40: 7708.33 | X40: 7708.33 | Y40: 7708.33 | Z40: 7708.33 | AA40: 92499.96 | AB40: =IF(N40="EUR",AA40,IF(N40="GBP",AA40/Rate!$C$3,AA40/Rate!$C$5)) -> 106321.79 | AC40: =IFERROR(VLOOKUP(K40,'4.2 Simplify Savings'!K:AB,18,0),0) -> 0 | AD40: =SUM(AB40:AC40) -> 106321.79
A41: =_xlfn.XLOOKUP(B41*1,'Reference '!I:I,'Reference '!K:K) -> Valerie Veyt | B41: =LEFT(C41,3) -> 602 | C41: 602_IS Operational_EIL_EUR | D41: 602_IS Operational_EIL_EUR | E41: 342001 - Systems support | F41: 342001 - Systems support | G41: 000000_Default | H41: 000000_Default | I41: 0000_Default | J41: 0000_Default | K41: Wifi Network Monitoring | L41: Xentrans / Netforecast | M41: Budget 2026 | N41: EUR | O41: 15000 | P41: 15000 | Q41: 15000 | R41: 15000 | S41: 15000 | T41: 15000 | U41: 15000 | V41: 15000 | W41: 15000 | X41: 15000 | Y41: 15000 | Z41: 15000 | AA41: 180000 | AB41: =IF(N41="EUR",AA41,IF(N41="GBP",AA41/Rate!$C$3,AA41/Rate!$C$5)) -> 180000 | AC41: =IFERROR(VLOOKUP(K41,'4.2 Simplify Savings'!K:AB,18,0),0) -> 0 | AD41: =SUM(AB41:AC41) -> 180000
A42: =_xlfn.XLOOKUP(B42*1,'Reference '!I:I,'Reference '!K:K) -> Valerie Veyt | B42: =LEFT(C42,3) -> 602 | C42: 602_IS Operational_EIL_EUR | D42: 602_IS Operational_EIL_EUR | E42: 342001 - Systems support | F42: 342001 - Systems support | G42: 000000_Default | H42: 000000_Default | I42: 0000_Default | J42: 0000_Default | K42: eRoster and Quintiq Maintenance and Planning TBC | L42: SOPRA STERIA BENELUX SA | M42: Budget 2026 | N42: EUR | O42: 10000 | P42: 10000 | Q42: 10000 | R42: 10000 | S42: 10000 | T42: 10000 | U42: 10000 | V42: 10000 | W42: 10000 | X42: 10000 | Y42: 10000 | Z42: 10000 | AA42: 120000 | AB42: =IF(N42="EUR",AA42,IF(N42="GBP",AA42/Rate!$C$3,AA42/Rate!$C$5)) -> 120000 | AC42: =IFERROR(VLOOKUP(K42,'4.2 Simplify Savings'!K:AB,18,0),0) -> 0 | AD42: =SUM(AB42:AC42) -> 120000
...

Sheet 2.2 EIL COS
Y3: Total | Z3: =SUBTOTAL(9,Z5:Z22) -> 13274936
A4: Cost center manager | B4: Is Split Child Row | C4: Level Code | D4: Level Name | E4: Account Code Code | F4: Account Code Name | G4: Counterparty Code | H4: Counterparty Name | I4: Project Code | J4: Project Name | K4: Description | L4: Level Currency | M4: Jan-2026 | N4: Feb-2026 | O4: Mar-2026 | P4: Apr-2026 | Q4: May-2026 | R4: Jun-2026 | S4: Jul-2026 | T4: Aug-2026 | U4: Sep-2026 | V4: Oct-2026 | W4: Nov-2026 | X4: Dec-2026 | Y4: FY2026 | Z4: Cost in euros
A5: =_xlfn.XLOOKUP(B5*1,'Reference '!I:I,'Reference '!K:K) -> Xavier Romanet | B5: =LEFT(C5,3) -> 605 | C5: 605_IS Sales System_EIL_EUR | D5: 605_IS Sales System_EIL_EUR | E5: 230300 - GDS costs (CoS) | F5: 230300 - GDS costs (CoS) | G5: 000000_Default | H5: 000000_Default | I5: 0000_Default | J5: 0000_Default | K5: Amadeus CC Auth | L5: EUR | M5: 230 | N5: 230 | O5: 230 | P5: 230 | Q5: 230 | R5: 230 | S5: 230 | T5: 230 | U5: 230 | V5: 230 | W5: 230 | X5: 230 | Y5: 2760 | Z5: =IF(L5="EUR",Y5,IF(L5="GBP",Y5/[74]Rate!$C$3,Y5/[74]Rate!$C$5)) -> 2760
A6: =_xlfn.XLOOKUP(B6*1,'Reference '!I:I,'Reference '!K:K) -> Xavier Romanet | B6: =LEFT(C6,3) -> 605 | C6: 605_IS Sales System_EIL_USD | D6: 605_IS Sales System_EIL_USD | E6: 230300 - GDS costs (CoS) | F6: 230300 - GDS costs (CoS) | G6: 000000_Default | H6: 000000_Default | I6: 0000_Default | J6: 0000_Default | K6: ATPCO Fare filing services | L6: USD | M6: 594 | N6: 594 | O6: 594 | P6: 594 | Q6: 594 | R6: 594 | S6: 594 | T6: 594 | U6: 594 | V6: 594 | W6: 594 | X6: 594 | Y6: 7128 | Z6: =IF(L6="EUR",Y6,IF(L6="GBP",Y6/[74]Rate!$C$3,Y6/[74]Rate!$C$5)) -> 6092.3077
A7: =_xlfn.XLOOKUP(B7*1,'Reference '!I:I,'Reference '!K:K) -> Xavier Romanet | B7: =LEFT(C7,3) -> 605 | C7: 605_IS Sales System_EIL_USD | D7: 605_IS Sales System_EIL_USD | E7: 240200 - Hosting (CoS) | F7: 240200 - Hosting (CoS) | G7: 000000_Default | H7: 000000_Default | I7: 0000_Default | J7: 0000_Default | K7: AWS (USD) | L7: USD | M7: 96200 | N7: 96200 | O7: 96200 | P7: 96200 | Q7: 96200 | R7: 96200 | S7: 96200 | T7: 96200 | U7: 96200 | V7: 96200 | W7: 96200 | X7: 96200 | Y7: 1154400 | Z7: =IF(L7="EUR",Y7,IF(L7="GBP",Y7/[74]Rate!$C$3,Y7/[74]Rate!$C$5)) -> 986666.67
A8: =_xlfn.XLOOKUP(B8*1,'Reference '!I:I,'Reference '!K:K) -> Xavier Romanet | B8: =LEFT(C8,3) -> 605 | C8: 605_IS Sales System_EIL_EUR | D8: 605_IS Sales System_EIL_EUR | E8: 230300 - GDS costs (CoS) | F8: 230300 - GDS costs (CoS) | G8: 000000_Default | H8: 000000_Default | I8: 0000_Default | J8: 0000_Default | K8: BENErail | L8: EUR | M8: 60000 | N8: 60000 | O8: 60000 | P8: 60000 | Q8: 60000 | R8: 60000 | S8: 60000 | T8: 60000 | U8: 60000 | V8: 60000 | W8: 60000 | X8: 60000 | Y8: 720000 | Z8: =IF(L8="EUR",Y8,IF(L8="GBP",Y8/[74]Rate!$C$3,Y8/[74]Rate!$C$5)) -> 720000
A9: =_xlfn.XLOOKUP(B9*1,'Reference '!I:I,'Reference '!K:K) -> Mael Delmas | B9: =LEFT(C9,3) -> 604 | C9: 604_IS Customer Systems_EIL_GBP | D9: 604_IS Customer Systems_EIL_GBP | E9: 240200 - Hosting (CoS) | F9: 240200 - Hosting (CoS) | G9: 000000_Default | H9: 000000_Default | I9: 1052_RPO system | J9: 1052_RPO system | K9: Cazyn (Revenue Management Systems) | L9: GBP | M9: 82083.33 | N9: 82083.33 | O9: 82083.33 | P9: 82083.33 | Q9: 82083.33 | R9: 82083.33 | S9: 82083.33 | T9: 82083.33 | U9: 82083.33 | V9: 82083.33 | W9: 82083.33 | X9: 82083.33 | Y9: 984999.96 | Z9: =IF(L9="EUR",Y9,IF(L9="GBP",Y9/[74]Rate!$C$3,Y9/[74]Rate!$C$5)) -> 1132183.9
A10: =_xlfn.XLOOKUP(B10*1,'Reference '!I:I,'Reference '!K:K) -> Xavier Romanet | B10: =LEFT(C10,3) -> 605 | C10: 605_IS Sales System_EIL_EUR | D10: 605_IS Sales System_EIL_EUR | E10: 230300 - GDS costs (CoS) | F10: 230300 - GDS costs (CoS) | G10: 000000_Default | H10: 000000_Default | I10: 0000_Default | J10: 0000_Default | K10: EIL Amadeus Segment charges | L10: EUR | M10: 164988.46 | N10: 124206.88 | O10: 134532.67 | P10: 125092.51 | Q10: 118038.11 | R10: 111436.85 | S10: 105348.33 | T10: 104518.25 | U10: 130928.57 | V10: 124422.8 | W10: 114303.11 | X10: 90037.49 | Y10: 1447854 | Z10: =IF(L10="EUR",Y10,IF(L10="GBP",Y10/[74]Rate!$C$3,Y10/[74]Rate!$C$5)) -> 1447854
A11: =_xlfn.XLOOKUP(B11*1,'Reference '!I:I,'Reference '!K:K) -> Xavier Romanet | B11: =LEFT(C11,3) -> 605 | C11: 605_IS Sales System_EIL_EUR | D11: 605_IS Sales System_EIL_EUR | E11: 230100 - Distribution charges (CoS) | F11: 230100 - Distribution charges (CoS) | G11: E14_SNCF VOYAGES GRANDES LIGNES | H11: E14_SNCF VOYAGES GRANDES LIGNES | I11: 0000_Default | J11: 0000_Default | K11: EIL PAO Var fees (carrier agreement) | L11: EUR | M11: 18971.58 | N11: 14233.67 | O11: 15361.69 | P11: 14252.91 | Q11: 13447.31 | R11: 12719.11 | S11: 11972.06 | T11: 11724.41 | U11: 14919.74 | V11: 14280.46 | W11: 13143.71 | X11: 10396.31 | Y11: 165422.96 | Z11: =IF(L11="EUR",Y11,IF(L11="GBP",Y11/[74]Rate!$C$3,Y11/[74]Rate!$C$5)) -> 165422.96
A12: =_xlfn.XLOOKUP(B12*1,'Reference '!I:I,'Reference '!K:K) -> Xavier Romanet | B12: =LEFT(C12,3) -> 605 | C12: 605_IS Sales System_EIL_EUR | D12: 605_IS Sales System_EIL_EUR | E12: 230100 - Distribution charges (CoS) | F12: 230100 - Distribution charges (CoS) | G12: E14_SNCF VOYAGES GRANDES LIGNES | H12: E14_SNCF VOYAGES GRANDES LIGNES | I12: 0000_Default | J12: 0000_Default | K12: EIL PAO Var fees (distributor agreement) | L12: EUR | M12: 56132.5 | N12: 41928.5 | O12: 41280.02 | P12: 16457.04 | Q12: 16552.68 | R12: 24251.02 | S12: 53873.79 | T12: 44944.93 | U12: 68142.92 | V12: 54763.37 | W12: 44037.58 | X12: 29885.49 | Y12: 492249.84 | Z12: =IF(L12="EUR",Y12,IF(L12="GBP",Y12/[74]Rate!$C$3,Y12/[74]Rate!$C$5)) -> 492249.84
A13: =_xlfn.XLOOKUP(B13*1,'Reference '!I:I,'Reference '!K:K) -> Xavier Romanet | B13: =LEFT(C13,3) -> 605 | C13: 605_IS Sales System_EIL_USD | D13: 605_IS Sales System_EIL_USD | E13: 230300 - GDS costs (CoS) | F13: 230300 - GDS costs (CoS) | G13: 000000_Default | H13: 000000_Default | I13: 0000_Default | J13: 0000_Default | K13: EIL Sabre Segment charges | L13: USD | M13: 176132.32 | N13: 132596.22 | O13: 143619.45 | P13: 133541.66 | Q13: 126010.79 | R13: 118963.66 | S13: 112463.9 | T13: 111577.76 | U13: 139771.92 | V13: 132826.72 | W13: 122023.51 | X13: 96118.92 | Y13: 1545646.8 | Z13: =IF(L13="EUR",Y13,IF(L13="GBP",Y13/[74]Rate!$C$3,Y13/[74]Rate!$C$5)) -> 1321065.7
A14: =_xlfn.XLOOKUP(B14*1,'Reference '!I:I,'Reference '!K:K) -> Xavier Romanet | B14: =LEFT(C14,3) -> 605 | C14: 605_IS Sales System_EIL_EUR | D14: 605_IS Sales System_EIL_EUR | E14: 230100 - Distribution charges (CoS) | F14: 230100 - Distribution charges (CoS) | G14: 000000_Default | H14: 000000_Default | I14: 0000_Default | J14: 0000_Default | K14: EIL Sqills variable charge | L14: EUR | M14: 492229.77 | N14: 369301.58 | O14: 526680.15 | P14: 607529.78 | Q14: 573191.18 | R14: 542151.78 | S14: 510308.66 | T14: 499752.91 | U14: 440512.67 | V14: 370515.77 | W14: 341021.85 | X14: 269738.93 | Y14: 5542935 | Z14: =IF(L14="EUR",Y14,IF(L14="GBP",Y14/[74]Rate!$C$3,Y14/[74]Rate!$C$5)) -> 5542935
A15: =_xlfn.XLOOKUP(B15*1,'Reference '!I:I,'Reference '!K:K) -> Xavier Romanet | B15: =LEFT(C15,3) -> 605 | C15: 605_IS Sales System_EIL_GBP | D15: 605_IS Sales System_EIL_GBP | E15: 230300 - GDS costs (CoS) | F15: 230300 - GDS costs (CoS) | G15: 000000_Default | H15: 000000_Default | I15: 0000_Default | J15: 0000_Default | K15: EIL Travelport Segment charges | L15: GBP | M15: 94291.56 | N15: 70984.73 | O15: 76885.96 | P15: 71490.86 | Q15: 67459.25 | R15: 63686.6 | S15: 60206.99 | T15: 59732.6 | U15: 74826.2 | V15: 71108.12 | W15: 65324.68 | X15: 51456.78 | Y15: 827454.33 | Z15: =IF(L15="EUR",Y15,IF(L15="GBP",Y15/[74]Rate!$C$3,Y15/[74]Rate!$C$5)) -> 951096.93
A16: =_xlfn.XLOOKUP(B16*1,'Reference '!I:I,'Reference '!K:K) -> Xavier Romanet | B16: =LEFT(C16,3) -> 605 | C16: 605_IS Sales System_EIL_EUR | D16: 605_IS Sales System_EIL_EUR | E16: 230300 - GDS costs (CoS) | F16: 230300 - GDS costs (CoS) | G16: 000000_Default | H16: 000000_Default | I16: 0000_Default | J16: 0000_Default | K16: GDS Air Connection (Sqills fixed cost) | L16: EUR | M16: 8182.49 | N16: 8182.49 | O16: 8182.49 | P16: 8182.49 | Q16: 8182.49 | R16: 8182.49 | S16: 8182.49 | T16: 8182.49 | U16: 8182.49 | V16: 8182.49 | W16: 8182.49 | X16: 8182.49 | Y16: 98189.88 | Z16: =IF(L16="EUR",Y16,IF(L16="GBP",Y16/[74]Rate!$C$3,Y16/[74]Rate!$C$5)) -> 98189.88
... A22: =_xlfn.XLOOKUP(B22*1,'Reference '!I:I,'Reference '!K:K) -> Xavier Romanet | B22: =LEFT(C22,3) -> 605 | C22: 605_IS Sales System_EIL_GBP | D22: 605_IS Sales System_EIL_GBP | E22: 240001 - Software Licences and support (CoS) | F22: 240001 - Software Licences and support (CoS) | G22: 000000_Default | H22: 000000_Default | I22: 0000_Default | J22: 0000_Default | K22: Various Software & Tools | L22: GBP | M22: 18500 | N22: 18500 | O22: 18500 | P22: 18500 | Q22: 18500 | R22: 18500 | S22: 18500 | T22: 18500 | U22: 18500 | V22: 18500 | W22: 18500 | X22: 18500 | Y22: 222000 | Z22: =IF(L22="EUR",Y22,IF(L22="GBP",Y22/[74]Rate!$C$3,Y22/[74]Rate!$C$5)) -> 255172.41

Sheet 2.3 EIL Capex 
AP3: =SUBTOTAL(9,AP5:AP79) -> 26992811
A4: Is Split Child Row | B4: PARENT_ASSET_ID | C4: OWNED_LEASED | D4: Cost center manager | E4: Level (Cost Centre) Code | F4: Level (Cost Centre) Name | G4: Project Code | H4: Project Name | I4: Counterparty Code | J4: Counterparty Name | K4: Cost Centre Code | L4: Cost Centre Name | M4: Currency Level Code | N4: Currency Level Name | O4: Asset_Category_1 Code | P4: Asset_Category_1 Name | Q4: FP_Asset_Catergory_2 Code | R4: FP_Asset_Catergory_2 Name | S4: Asset Category 3 (20YP) Code | T4: Asset Category 3 (20YP) Name | U4: Description | V4: Detail | W4: Expected Asset Book cost (per Asset ID) | X4: REMAINING_LIFE_IN_MONTHS | Y4: Recongnition- Depn Start date | Z4: Asset Categorization at purchase Code | AA4: Asset Categorization at purchase Name | AB4: DEPRECIATE_FLAG | AC4: Jan-2026 | AD4: Feb-2026 | AE4: Mar-2026 | AF4: Apr-2026 | AG4: May-2026 | AH4: Jun-2026 | AI4: Jul-2026 | AJ4: Aug-2026 | AK4: Sep-2026 | AL4: Oct-2026 | AM4: Nov-2026 | AN4: Dec-2026 | AO4: FY2026 | AP4: Total in €
A5: No | C5: OWNED | D5: Blanche Derkenne | E5: 600_CIO_EIL_EUR | F5: 600_CIO_EIL_EUR | G5: 0000_Default | H5: 0000_Default | I5: 000000_Default | J5: 000000_Default | K5: 600 | L5: 600 | M5: EUR | N5: EUR | O5: SOFTWARE | P5: SOFTWARE | Q5: Software | R5: Software | S5: Software | T5: Software | U5: Cost savings Target | V5: Medium | W5: -5525316 | X5: 48 | Y5: 1/1/2027 | Z5: CIP | AA5: CIP | AB5: YES | AC5: -460443 | AD5: -460443 | AE5: -460443 | AF5: -460443 | AG5: -460443 | AH5: -460443 | AI5: -460443 | AJ5: -460443 | AK5: -460443 | AL5: -460443 | AM5: -460443 | AN5: -460443 | AO5: -5525316 | AP5: =IF(N5="EUR",AO5,IF(N5="GBP",AO5/Rate!$C$3,'2.3 EIL Capex '!AO34/Rate!$C$5)) -> -5525316 | AQ5: << Centralised IS cost saving target to come back in line with the business plan
A6: No | C6: OWNED | D6: Ben Gbeve | E6: 601_IS Service Delivery_EIL_EUR | F6: 601_IS Service Delivery_EIL_EUR | G6: 0000_Default | H6: 0000_Default | I6: 000000_Default | J6: 000000_Default | K6: 601 | L6: 601 | M6: EUR | N6: EUR | O6: SOFTWARE | P6: SOFTWARE | Q6: Software | R6: Software | S6: Software | T6: Software | U6: Android / IOS Consolidation | V6: Medium | W6: 125004 | X6: 48 | Y6: 1/1/2027 | Z6: CIP | AA6: CIP | AB6: YES | AC6: 10417 | AD6: 10417 | AE6: 10417 | AF6: 10417 | AG6: 10417 | AH6: 10417 | AI6: 10417 | AJ6: 10417 | AK6: 10417 | AL6: 10417 | AM6: 10417 | AN6: 10417 | AO6: 125004 | AP6: =IF(N6="EUR",AO6,IF(N6="GBP",AO6/Rate!$C$3,'2.3 EIL Capex '!AO25/Rate!$C$5)) -> 125004
A7: No | C7: OWNED | D7: Ben Gbeve | E7: 601_IS Service Delivery_EIL_EUR | F7: 601_IS Service Delivery_EIL_EUR | G7: 0000_Default | H7: 0000_Default | I7: 000000_Default | J7: 000000_Default | K7: 601 | L7: 601 | M7: EUR | N7: EUR | O7: SOFTWARE | P7: SOFTWARE | Q7: Software | R7: Software | S7: Software | T7: Software | U7: Cloud PKI | V7: Medium | W7: 50004 | X7: 48 | Y7: 1/1/2027 | Z7: CIP | AA7: CIP | AB7: YES | AC7: 4167 | AD7: 4167 | AE7: 4167 | AF7: 4167 | AG7: 4167 | AH7: 4167 | AI7: 4167 | AJ7: 4167 | AK7: 4167 | AL7: 4167 | AM7: 4167 | AN7: 4167 | AO7: 50004 | AP7: =IF(N7="EUR",AO7,IF(N7="GBP",AO7/Rate!$C$3,'2.3 EIL Capex '!AO28/Rate!$C$5)) -> 50004
A8: No | C8: OWNED | D8: Ben Gbeve | E8: 601_IS Service Delivery_EIL_EUR | F8: 601_IS Service Delivery_EIL_EUR | G8: 0000_Default | H8: 0000_Default | I8: 000000_Default | J8: 000000_Default | K8: 601 | L8: 601 | M8: EUR | N8: EUR | O8: SOFTWARE | P8: SOFTWARE | Q8: Software | R8: Software | S8: Software | T8: Software | U8: Consolidated solution for Cloud Back up & DR | V8: Medium | W8: 99996 | X8: 48 | Y8: 1/1/2027 | Z8: CIP | AA8: CIP | AB8: YES | AC8: 8333 | AD8: 8333 | AE8: 8333 | AF8: 8333 | AG8: 8333 | AH8: 8333 | AI8: 8333 | AJ8: 8333 | AK8: 8333 | AL8: 8333 | AM8: 8333 | AN8: 8333 | AO8: 99996 | AP8: =IF(N8="EUR",AO8,IF(N8="GBP",AO8/Rate!$C$3,'2.3 EIL Capex '!AO30/Rate!$C$5)) -> 99996
A9: No | C9: OWNED | D9: Ben Gbeve | E9: 601_IS Service Delivery_EIL_EUR | F9: 601_IS Service Delivery_EIL_EUR | G9: 0000_Default | H9: 0000_Default | I9: 000000_Default | J9: 000000_Default | K9: 601 | L9: 601 | M9: EUR | N9: EUR | O9: SOFTWARE | P9: SOFTWARE | Q9: Software | R9: Software | S9: Software | T9: Software | U9: Customer Information System refresh | V9: Medium | W9: 99996 | X9: 48 | Y9: 1/1/2027 | Z9: CIP | AA9: CIP | AB9: YES | AC9: 8333 | AD9: 8333 | AE9: 8333 | AF9: 8333 | AG9: 8333 | AH9: 8333 | AI9: 8333 | AJ9: 8333 | AK9: 8333 | AL9: 8333 | AM9: 8333 | AN9: 8333 | AO9: 99996 | AP9: =IF(N9="EUR",AO9,IF(N9="GBP",AO9/Rate!$C$3,'2.3 EIL Capex '!AO35/Rate!$C$5)) -> 99996
A10: No | C10: OWNED | D10: Ben Gbeve | E10: 601_IS Service Delivery_EIL_EUR | F10: 601_IS Service Delivery_EIL_EUR | G10: 0000_Default | H10: 0000_Default | I10: 000000_Default | J10: 000000_Default | K10: 601 | L10: 601 | M10: EUR | N10: EUR | O10: SOFTWARE | P10: SOFTWARE | Q10: Software | R10: Software | S10: Software | T10: Software | U10: DevOps pipeline and containers | V10: Medium | W10: 9996 | X10: 48 | Y10: 1/1/2027 | Z10: CIP | AA10: CIP | AB10: YES | AC10: 833 | AD10: 833 | AE10: 833 | AF10: 833 | AG10: 833 | AH10: 833 | AI10: 833 | AJ10: 833 | AK10: 833 | AL10: 833 | AM10: 833 | AN10: 833 | AO10: 9996 | AP10: =IF(N10="EUR",AO10,IF(N10="GBP",AO10/Rate!$C$3,'2.3 EIL Capex '!AO39/Rate!$C$5)) -> 9996
A11: No | C11: OWNED | D11: Ben Gbeve | E11: 601_IS Service Delivery_EIL_EUR | F11: 601_IS Service Delivery_EIL_EUR | G11: 0000_Default | H11: 0000_Default | I11: 000000_Default | J11: 000000_Default | K11: 601 | L11: 601 | M11: EUR | N11: EUR | O11: PLANT AND MACHINERY | P11: PLANT AND MACHINERY | Q11: It Equipments | R11: It Equipments | S11: Plant & Machinery - IT equipment | T11: Plant & Machinery - IT equipment | U11: Hardware BAU | V11: Medium | W11: 219996 | X11: 48 | Y11: 1/1/2027 | Z11: CIP | AA11: CIP | AB11: YES | AC11: 18333 | AD11: 18333 | AE11: 18333 | AF11: 18333 | AG11: 18333 | AH11: 18333 | AI11: 18333 | AJ11: 18333 | AK11: 18333 | AL11: 18333 | AM11: 18333 | AN11: 18333 | AO11: 219996 | AP11: =IF(N11="EUR",AO11,IF(N11="GBP",AO11/Rate!$C$3,'2.3 EIL Capex '!AO45/Rate!$C$5)) -> 219996
A12: No | C12: OWNED | D12: Ben Gbeve | E12: 601_IS Service Delivery_EIL_EUR | F12: 601_IS Service Delivery_EIL_EUR | G12: 0000_Default | H12: 0000_Default | I12: 000000_Default | J12: 000000_Default | K12: 601 | L12: 601 | M12: EUR | N12: EUR | O12: SOFTWARE | P12: SOFTWARE | Q12: Software | R12: Software | S12: Software | T12: Software | U12: Home drives (H) to OneDrive | V12: Medium | W12: 60000 | X12: 48 | Y12: 1/1/2027 | Z12: CIP | AA12: CIP | AB12: YES | AC12: 5000 | AD12: 5000 | AE12: 5000 | AF12: 5000 | AG12: 5000 | AH12: 5000 | AI12: 5000 | AJ12: 5000 | AK12: 5000 | AL12: 5000 | AM12: 5000 | AN12: 5000 | AO12: 60000 | AP12: =IF(N12="EUR",AO12,IF(N12="GBP",AO12/Rate!$C$3,'2.3 EIL Capex '!AO46/Rate!$C$5)) -> 60000
A13: No | C13: OWNED | D13: Ben Gbeve | E13: 601_IS Service Delivery_EIL_EUR | F13: 601_IS Service Delivery_EIL_EUR | G13: 0000_Default | H13: 0000_Default | I13: 000000_Default | J13: 000000_Default | K13: 601 | L13: 601 | M13: EUR | N13: EUR | O13: SOFTWARE | P13: SOFTWARE | Q13: Software | R13: Software | S13: Software | T13: Software | U13: ISLOG Replacement | V13: Medium | W13: 60000 | X13: 48 | Y13: 1/1/2027 | Z13: CIP | AA13: CIP | AB13: YES | AC13: 5000 | AD13: 5000 | AE13: 5000 | AF13: 5000 | AG13: 5000 | AH13: 5000 | AI13: 5000 | AJ13: 5000 | AK13: 5000 | AL13: 5000 | AM13: 5000 | AN13: 5000 | AO13: 60000 | AP13: =IF(N13="EUR",AO13,IF(N13="GBP",AO13/Rate!$C$3,'2.3 EIL Capex '!AO48/Rate!$C$5)) -> 60000
A14: No | C14: OWNED | D14: Ben Gbeve | E14: 601_IS Service Delivery_EIL_EUR | F14: 601_IS Service Delivery_EIL_EUR | G14: 0000_Default | H14: 0000_Default | I14: 000000_Default | J14: 000000_Default | K14: 601 | L14: 601 | M14: EUR | N14: EUR | O14: SOFTWARE | P14: SOFTWARE | Q14: Software | R14: Software | S14: Software | T14: Software | U14: Lounge Enhancements/Customer Exerience (Wi-Fi / IPTV / Portal) | V14: Medium | W14: 90000 | X14: 48 | Y14: 1/1/2027 | Z14: CIP | AA14: CIP | AB14: YES | AC14: 7500 | AD14: 7500 | AE14: 7500 | AF14: 7500 | AG14: 7500 | AH14: 7500 | AI14: 7500 | AJ14: 7500 | AK14: 7500 | AL14: 7500 | AM14: 7500 | AN14: 7500 | AO14: 90000 | AP14: =IF(N14="EUR",AO14,IF(N14="GBP",AO14/Rate!$C$3,'2.3 EIL Capex '!AO49/Rate!$C$5)) -> 90000
A15: No | C15: OWNED | D15: Ben Gbeve | E15: 601_IS Service Delivery_EIL_EUR | F15: 601_IS Service Delivery_EIL_EUR | G15: 0000_Default | H15: 0000_Default | I15: 000000_Default | J15: 000000_Default | K15: 601 | L15: 601 | M15: EUR | N15: EUR | O15: SOFTWARE | P15: SOFTWARE | Q15: Software | R15: Software | S15: Software | T15: Software | U15: OCC Disaster Recovery | V15: Medium | W15: 60000 | X15: 48 | Y15: 1/1/2027 | Z15: CIP | AA15: CIP | AB15: YES | AC15: 5000 | AD15: 5000 | AE15: 5000 | AF15: 5000 | AG15: 5000 | AH15: 5000 | AI15: 5000 | AJ15: 5000 | AK15: 5000 | AL15: 5000 | AM15: 5000 | AN15: 5000 | AO15: 60000 | AP15: =IF(N15="EUR",AO15,IF(N15="GBP",AO15/Rate!$C$3,'2.3 EIL Capex '!AO54/Rate!$C$5)) -> 60000
A16: No | C16: OWNED | D16: Ben Gbeve | E16: 601_IS Service Delivery_EIL_EUR | F16: 601_IS Service Delivery_EIL_EUR | G16: 0000_Default | H16: 0000_Default | I16: 000000_Default | J16: 000000_Default | K16: 601 | L16: 601 | M16: EUR | N16: EUR | O16: PLANT AND MACHINERY | P16: PLANT AND MACHINERY | Q16: It Equipments | R16: It Equipments | S16: Plant & Machinery - IT equipment | T16: Plant & Machinery - IT equipment | U16: Paris | V16: Medium | W16: 401268 | X16: 48 | Y16: 1/1/2027 | Z16: CIP | AA16: CIP | AB16: YES | AC16: 33439 | AD16: 33439 | AE16: 33439 | AF16: 33439 | AG16: 33439 | AH16: 33439 | AI16: 33439 | AJ16: 33439 | AK16: 33439 | AL16: 33439 | AM16: 33439 | AN16: 33439 | AO16: 401268 | AP16: =IF(N16="EUR",AO16,IF(N16="GBP",AO16/Rate!$C$3,'2.3 EIL Capex '!AO59/Rate!$C$5)) -> 401268
A17: No | C17: OWNED | D17: Ben Gbeve | E17: 601_IS Service Delivery_EIL_EUR | F17: 601_IS Service Delivery_EIL_EUR | G17: 0000_Default | H17: 0000_Default | I17: 000000_Default | J17: 000000_Default | K17: 601 | L17: 601 | M17: EUR | N17: EUR | O17: SOFTWARE | P17: SOFTWARE | Q17: Software | R17: Software | S17: Software | T17: Software | U17: Passwordless | V17: Medium | W17: 9996 | X17: 48 | Y17: 1/1/2027 | Z17: CIP | AA17: CIP | AB17: YES | AC17: 833 | AD17: 833 | AE17: 833 | AF17: 833 | AG17: 833 | AH17: 833 | AI17: 833 | AJ17: 833 | AK17: 833 | AL17: 833 | AM17: 833 | AN17: 833 | AO17: 9996 | AP17: =IF(N17="EUR",AO17,IF(N17="GBP",AO17/Rate!$C$3,'2.3 EIL Capex '!AO60/Rate!$C$5)) -> 9996
A18: No | C18: OWNED | D18: Ben Gbeve | E18: 601_IS Service Delivery_EIL_EUR | F18: 601_IS Service Delivery_EIL_EUR | G18: 0000_Default | H18: 0000_Default | I18: 000000_Default | J18: 000000_Default | K18: 601 | L18: 601 | M18: EUR | N18: EUR | O18: SOFTWARE | P18: SOFTWARE | Q18: Software | R18: Software | S18: Software | T18: Software | U18: Proactive laptop refresh & consolidation | V18: Medium | W18: 200004 | X18: 48 | Y18: 1/1/2027 | Z18: CIP | AA18: CIP | AB18: YES | AC18: 16667 | AD18: 16667 | AE18: 16667 | AF18: 16667 | AG18: 16667 | AH18: 16667 | AI18: 16667 | AJ18: 16667 | AK18: 16667 | AL18: 16667 | AM18: 16667 | AN18: 16667 | AO18: 200004 | AP18: =IF(N18="EUR",AO18,IF(N18="GBP",AO18/Rate!$C$3,'2.3 EIL Capex '!AO63/Rate!$C$5)) -> 200004
A19: No | C19: OWNED | D19: Ben Gbeve | E19: 601_IS Service Delivery_EIL_EUR | F19: 601_IS Service Delivery_EIL_EUR | G19: 0000_Default | H19: 0000_Default | I19: 000000_Default | J19: 000000_Default | K19: 601 | L19: 601 | M19: EUR | N19: EUR | O19: SOFTWARE | P19: SOFTWARE | Q19: Software | R19: Software | S19: Software | T19: Software | U19: SD-WAN / SASE / Consolidate VPN | V19: Medium | W19: 99996 | X19: 48 | Y19: 1/1/2027 | Z19: CIP | AA19: CIP | AB19: YES | AC19: 8333 | AD19: 8333 | AE19: 8333 | AF19: 8333 | AG19: 8333 | AH19: 8333 | AI19: 8333 | AJ19: 8333 | AK19: 8333 | AL19: 8333 | AM19: 8333 | AN19: 8333 | AO19: 99996 | AP19: =IF(N19="EUR",AO19,IF(N19="GBP",AO19/Rate!$C$3,'2.3 EIL Capex '!AO69/Rate!$C$5)) -> 99996
A20: No | C20: OWNED | D20: Ben Gbeve | E20: 601_IS Service Delivery_EIL_EUR | F20: 601_IS Service Delivery_EIL_EUR | G20: 0000_Default | H20: 0000_Default | I20: 000000_Default | J20: 000000_Default | K20: 601 | L20: 601 | M20: EUR | N20: EUR | O20: SOFTWARE | P20: SOFTWARE | Q20: Software | R20: Software | S20: Software | T20: Software | U20: SPI Phase 2 | V20: Medium | W20: 174996 | X20: 48 | Y20: 1/1/2027 | Z20: CIP | AA20: CIP | AB20: YES | AC20: 14583 | AD20: 14583 | AE20: 14583 | AF20: 14583 | AG20: 14583 | AH20: 14583 | AI20: 14583 | AJ20: 14583 | AK20: 14583 | AL20: 14583 | AM20: 14583 | AN20: 14583 | AO20: 174996 | AP20: =IF(N20="EUR",AO20,IF(N20="GBP",AO20/Rate!$C$3,'2.3 EIL Capex '!AO71/Rate!$C$5)) -> 174996
A21: No | C21: OWNED | D21: Ben Gbeve | E21: 601_IS Service Delivery_EIL_EUR | F21: 601_IS Service Delivery_EIL_EUR | G21: 0000_Default | H21: 0000_Default | I21: 000000_Default | J21: 000000_Default | K21: 601 | L21: 601 | M21: EUR | N21: EUR | O21: SOFTWARE | P21: SOFTWARE | Q21: Software | R21: Software | S21: Software | T21: Software | U21: Station Wi-Fi (for mobility) | V21: Medium | W21: 129996 | X21: 48 | Y21: 1/1/2027 | Z21: CIP | AA21: CIP | AB21: YES | AC21: 10833 | AD21: 10833 | AE21: 10833 | AF21: 10833 | AG21: 10833 | AH21: 10833 | AI21: 10833 | AJ21: 10833 | AK21: 10833 | AL21: 10833 | AM21: 10833 | AN21: 10833 | AO21: 129996 | AP21: =IF(N21="EUR",AO21,IF(N21="GBP",AO21/Rate!$C$3,'2.3 EIL Capex '!AO72/Rate!$C$5)) -> 129996
A22: No | C22: OWNED | D22: Ben Gbeve | E22: 601_IS Service Delivery_EIL_EUR | F22: 601_IS Service Delivery_EIL_EUR | G22: 0000_Default | H22: 0000_Default | I22: 000000_Default | J22: 000000_Default | K22: 601 | L22: 601 | M22: EUR | N22: EUR | O22: SOFTWARE | P22: SOFTWARE | Q22: Software | R22: Software | S22: Software | T22: Software | U22: Stations improvements | V22: Medium | W22: 150000 | X22: 48 | Y22: 1/1/2027 | Z22: CIP | AA22: CIP | AB22: YES | AC22: 12500 | AD22: 12500 | AE22: 12500 | AF22: 12500 | AG22: 12500 | AH22: 12500 | AI22: 12500 | AJ22: 12500 | AK22: 12500 | AL22: 12500 | AM22: 12500 | AN22: 12500 | AO22: 150000 | AP22: =IF(N22="EUR",AO22,IF(N22="GBP",AO22/Rate!$C$3,'2.3 EIL Capex '!AO74/Rate!$C$5)) -> 150000
