Workbook
Name _20EURRATE: #REF!
Name Account_codes: #REF!
Name archCost: #REF!
Name AshfordLeaseAssetCfProfile: #REF!
Name AshfordLeaseCurrentAssetCfProfile: #REF!
Name AshfordLeaseLongTermCreditorCfProfile: #REF!
Name AshfordLeaseNonCurrentAssetCfProfile: #REF!
Name AshfordLeaseShortTermCreditorCfProfile: #REF!
Name AuditFailsStructural: #REF!
Name Bud_Exch_Rate: #REF!
Name Bud_exch_rateUSD: #REF!
Name BudExRate: 1.37
Name budExRateUSD: 1.5
Name budRate: #REF!
Name BusinessDevelopment_Integration: 'System List'!$AT$5:$AT$10
Name capexMonths: #REF!
Name CashManagementActionsEUR: #REF!
Name CashManagementActionsGBP: #REF!
Name CashManagementActionsUSD: #REF!
Name CHANGE_Impact_Score: 'System List'!$S$4:$T$115
Name Commercial: 'System List'!$AD$5:$AD$12
Name Communication_DI: 'System List'!$AX$5:$AX$7
Name CostSalesTicketVariableAllEURPctIn: #REF!
Name CostSalesTicketVariableAllGBPPctIn: #REF!
Name CostSalesTicketVariableAllUSDPctIn: #REF!
Name CostSalesTicketVariableEILEURPctIn: #REF!
Name CostSalesTicketVariableEILGBPPctIn: #REF!
Name CostSalesTicketVariableEILUSDPctIn: #REF!
Name CostSalesTicketVariableOtherEURPctIn: #REF!
Name CostSalesTicketVariableOtherGBPPctIn: #REF!
Name CostSalesTicketVariableOtherUSDPctIn: #REF!
Name CostTrainLeasesProfileEUR: #REF!
Name CostTrainLeasesProfileGBP: #REF!
Name Counterparties: #REF!
Name dataCharERR: "ERR"
Name dataCharOK: "ok"
Name dataCharWARN: "WARN"
Name DateActualsEnd: #REF!
Name Days360: #REF!
Name Days365: #REF!
Name DaysInYear: 365
Name DaysPaymentsOutstanding: #REF!
Name DaysSalesOutstanding: #REF!
Name dbaCost: #REF!
Name dc5YPend: #REF!
Name dc5YPstart: #REF!
Name dcActualsMonth: #REF!
Name dcActualsYear: #REF!
Name dcAMSe320min: #REF!
Name dcBalSheetTol: 0.2
Name dcBEAMAlabourIndexApr14: #REF!
Name dcBEAMAmaterialsIndexApr14: #REF!
Name dcBEprepayEC4T: #REF!
Name dcBEprepayTAC: #REF!
Name dcBStol: #REF!
Name dcBudgetMode: #REF!
Name dcCashAdjustSwitch: #REF!
Name dcCurrentYear: #REF!
Name dcCurrentYearText: #REF!
Name dcDateFirstOptionUnit: #REF!

Sheet Instructions
A1: 2025 Synchro Plan - Step 1 - Value/Effort Instruction
A6: We recommend you to open the file in the desktop app for a better experience | C6: >>>
A8: Tab | B8: Description
A9: Input | B9: This is the most important tab where we are gathering your input in term of: - Project Deliverables - Project Start and End Dates - Project Value and contribution toward Group Strategic KPI - High Level Resource estimations by project and by departements: Low, Medium, High (when a department is not impacted, please, leave the cell blank) - High Level Change Impact estimations by project and by departements: Low, Medium, High (when a department is not impacted, please, leave the cell blank) A description of each column will apear when you hover your mouse on the column title (only if open on desktop app) + you will have indication on how to score Low (L), Medium (M) and High (H) on top of each section. If you want to modify the name of a project - please do it directly and re-word as you see fit If you want to split a specific line in 2 or several projects -> you can add line at the bottom of the list (you will not be able to insert a line) If you want to remove a project - delete the content of the line (leave it blank) Any questions / issues - please do not hesitate to contact us: nicolas.madier@eurostar.com lucie.jeunemaitre@eurostar.com
A10: Checklist | B10: This are few elements to take into account when estimating in the Resources and Change impact of your project
A11: Project Map Benefits - Effort | B11: This is an automated chart where projects will be ploted according to Value score and Effort Score
A12: Heat Map Change | B12: This is an automated table, a heat map showing when each department will be most impacted in term of changes.
A13: Heat Map Workload | B13: This is an automated table, a heat map showing when each department will be the most solicited by project delivery

Sheet Checklist
B1: CHECK List Have you thought about…?
C4: HR
C5: Will your project impact the roles & responsibilities, ways of working, working conditions of other colleagues? if yes on any of this, make sure you consult our HR team to check if Union Consultation is required and/or job descriptions must evolve Might you need additional resources, recruitment to deliver the project - therefore, might you need HR to do so?
C8: Communication interne
C9: Might your project involved several departments and might need to have internal communication support? Might you need communication material to be sent group wise?
C12: External Communication / Customer Comms / Marketing / Press
C13: Will you project requires to be communicated to Customers (will it need to be "commercially launched")? Will you project requires to be communicated to Shareholders?
C16: Finance & Procurement
C17: Will you need specific budget for your project? Will you need to go through the commitment board: >50K for consultancy & >250k for Project total cost if so - you will need Finance Support
C20: IS
C21: Will your project lead to improvement or creation of IS tools; if yes, have you already discuss your ambition with the IT/IS teams? Is is already on the IS/IT pipeline?

Sheet Input
B1: TPO Portfolio | G1: see in PowerBI | N1: VALUE SCORING L = Small Contribution to Strategic KPI M = Significant Contribution to Strategic KPI H = Big Contribution to Strategic KPI | V1: Estimation of Workload per Team No resources needed = leave Blank L = Less than 1 FTE needed for the length of the project (light contribution e.g. for workshop / follow up) M = Between 1 and 2 FTE needed for the length of the project (actively contributed to the project) H = More than 2 FTE needed for the length of the project (significant resource needed for the project) | AG1: Estimation on CHANGE IMPACT per Department when delivered L = Small changes on processes / tool for a small number of colleagues (<10 people) M = Significant changes for small number of colleagues OR small changes impacting high number colleagues H = Significant changes on processes / tools for high number colleagues OR any organisational changes | AS1: =VLOOKUP([@Duration];Duration;2;FALSE)+[@[Resource Score]]+[@[CHANGE Impact Score]] | AZ1: 1.1364 | BA1: 1.1364 | BC1: 1.1364 | BF1: CALCULATION | BH1: Change Impact SCORE | BT1: Resource Impact Score | CX1: ='System List'!$AB$5 -> CORPHRFIN | CY1: ='System List'!$AB$5 -> CORPHRFIN | CZ1: ='System List'!$AB$5 -> CORPHRFIN | DA1: ='System List'!$AB$5 -> CORPHRFIN | DB1: ='System List'!$AB$5 -> CORPHRFIN | DC1: ='System List'!$AB$5 -> CORPHRFIN | DD1: ='System List'!$AB$5 -> CORPHRFIN | DE1: ='System List'!$AB$5 -> CORPHRFIN | DF1: ='System List'!$AB$5 -> CORPHRFIN | DH1: ='System List'!$AB$6 -> CUST | DI1: ='System List'!$AB$6 -> CUST | DJ1: ='System List'!$AB$6 -> CUST | DK1: ='System List'!$AB$6 -> CUST | DL1: ='System List'!$AB$6 -> CUST | DM1: ='System List'!$AB$6 -> CUST | DN1: ='System List'!$AB$6 -> CUST | DO1: ='System List'!$AB$6 -> CUST | DP1: ='System List'!$AB$6 -> CUST | DR1: ='System List'!$AB$7 -> CYBER | DS1: ='System List'!$AB$7 -> CYBER | DT1: ='System List'!$AB$7 -> CYBER | DU1: ='System List'!$AB$7 -> CYBER | DV1: ='System List'!$AB$7 -> CYBER | DW1: ='System List'!$AB$7 -> CYBER | DX1: ='System List'!$AB$7 -> CYBER | DY1: ='System List'!$AB$7 -> CYBER | DZ1: ='System List'!$AB$7 -> CYBER | EB1: ='System List'!$AB$8 -> DATA | EC1: ='System List'!$AB$8 -> DATA | ED1: ='System List'!$AB$8 -> DATA | EE1: ='System List'!$AB$8 -> DATA | EF1: ='System List'!$AB$8 -> DATA | EG1: ='System List'!$AB$8 -> DATA | EH1: ='System List'!$AB$8 -> DATA | EI1: ='System List'!$AB$8 -> DATA | EJ1: ='System List'!$AB$8 -> DATA | EL1: ='System List'!$AB$10 -> INFRA | EM1: ='System List'!$AB$10 -> INFRA | EN1: ='System List'!$AB$10 -> INFRA | EO1: ='System List'!$AB$10 -> INFRA | EP1: ='System List'!$AB$10 -> INFRA | EQ1: ='System List'!$AB$10 -> INFRA | ER1: ='System List'!$AB$10 -> INFRA | ES1: ='System List'!$AB$10 -> INFRA | ET1: ='System List'!$AB$10 -> INFRA | EV1: ='System List'!$AB$11 -> OPERATIONS | EW1: ='System List'!$AB$11 -> OPERATIONS | EX1: ='System List'!$AB$11 -> OPERATIONS | EY1: ='System List'!$AB$11 -> OPERATIONS | EZ1: ='System List'!$AB$11 -> OPERATIONS | FA1: ='System List'!$AB$11 -> OPERATIONS | FB1: ='System List'!$AB$11 -> OPERATIONS | FC1: ='System List'!$AB$11 -> OPERATIONS | FD1: ='System List'!$AB$11 -> OPERATIONS | FF1: ='System List'!$AB$12 -> PMO | FG1: ='System List'!$AB$12 -> PMO | FH1: ='System List'!$AB$12 -> PMO | FI1: ='System List'!$AB$12 -> PMO | FJ1: ='System List'!$AB$12 -> PMO | FK1: ='System List'!$AB$12 -> PMO | FL1: ='System List'!$AB$12 -> PMO | FM1: ='System List'!$AB$12 -> PMO | FN1: ='System List'!$AB$12 -> PMO | FP1: ='System List'!#REF! -> #REF! | FQ1: ='System List'!#REF! -> #REF! | FR1: ='System List'!#REF! -> #REF! | FS1: ='System List'!#REF! -> #REF! | FT1: ='System List'!#REF! -> #REF! | FU1: ='System List'!#REF! -> #REF! | FV1: ='System List'!#REF! -> #REF! | FW1: ='System List'!#REF! -> #REF! | FX1: ='System List'!#REF! -> #REF! | GB1: =BH2 -> Impact on - CIAL | GC1: =GB1 -> Impact on - CIAL | GD1: =GC1 -> Impact on - CIAL | GE1: =GD1 -> Impact on - CIAL | GF1: =GE1 -> Impact on - CIAL | GG1: =GF1 -> Impact on - CIAL | GH1: =GG1 -> Impact on - CIAL | GI1: =GH1 -> Impact on - CIAL | GJ1: =GI1 -> Impact on - CIAL | GL1: =BI2 -> Impact on - COM | GM1: =GL1 -> Impact on - COM | GN1: =GM1 -> Impact on - COM | GO1: =GN1 -> Impact on - COM | GP1: =GO1 -> Impact on - COM | GQ1: =GP1 -> Impact on - COM | GR1: =GQ1 -> Impact on - COM | GS1: =GR1 -> Impact on - COM | GT1: =GS1 -> Impact on - COM | GV1: =BJ2 -> Impact on - FIN | GW1: =GV1 -> Impact on - FIN | GX1: =GW1 -> Impact on - FIN | GY1: =GX1 -> Impact on - FIN | GZ1: =GY1 -> Impact on - FIN | HA1: =GZ1 -> Impact on - FIN | HB1: =HA1 -> Impact on - FIN | HC1: =HB1 -> Impact on - FIN | HD1: =HC1 -> Impact on - FIN | HF1: =BK2 -> Impact on - GEN SEC | HG1: =HF1 -> Impact on - GEN SEC | HH1: =HG1 -> Impact on - GEN SEC | HI1: =HH1 -> Impact on - GEN SEC | HJ1: =HI1 -> Impact on - GEN SEC | HK1: =HJ1 -> Impact on - GEN SEC | HL1: =HK1 -> Impact on - GEN SEC | HM1: =HL1 -> Impact on - GEN SEC | HN1: =HM1 -> Impact on - GEN SEC | HP1: =BL2 -> Impact on - HR | HQ1: =HP1 -> Impact on - HR | HR1: =HQ1 -> Impact on - HR | HS1: =HR1 -> Impact on - HR | HT1: =HS1 -> Impact on - HR | HU1: =HT1 -> Impact on - HR | HV1: =HU1 -> Impact on - HR | HW1: =HV1 -> Impact on - HR | HX1: =HW1 -> Impact on - HR | HZ1: =BM2 -> Impact on - IS | IA1: =HZ1 -> Impact on - IS | IB1: =IA1 -> Impact on - IS | IC1: =IB1 -> Impact on - IS | ID1: =IC1 -> Impact on - IS | IE1: =ID1 -> Impact on - IS | IF1: =IE1 -> Impact on - IS | IG1: =IF1 -> Impact on - IS | IH1: =IG1 -> Impact on - IS | IJ1: =BN2 -> Impact on - OPS | IK1: =IJ1 -> Impact on - OPS | IL1: =IK1 -> Impact on - OPS | IM1: =IL1 -> Impact on - OPS | IN1: =IM1 -> Impact on - OPS | IO1: =IN1 -> Impact on - OPS | IP1: =IO1 -> Impact on - OPS | IQ1: =IP1 -> Impact on - OPS | IR1: =IQ1 -> Impact on - OPS | IT1: =BO2 -> Impact on - ROLL STOCK | IU1: =IT1 -> Impact on - ROLL STOCK | IV1: =IU1 -> Impact on - ROLL STOCK | IW1: =IV1 -> Impact on - ROLL STOCK | IX1: =IW1 -> Impact on - ROLL STOCK | IY1: =IX1 -> Impact on - ROLL STOCK | IZ1: =IY1 -> Impact on - ROLL STOCK | JA1: =IZ1 -> Impact on - ROLL STOCK | JB1: =JA1 -> Impact on - ROLL STOCK | JD1: =BP2 -> Impact on - SAFETY | JE1: =JD1 -> Impact on - SAFETY | JF1: =JE1 -> Impact on - SAFETY | JG1: =JF1 -> Impact on - SAFETY | JH1: =JG1 -> Impact on - SAFETY | JI1: =JH1 -> Impact on - SAFETY | JJ1: =JI1 -> Impact on - SAFETY | JK1: =JJ1 -> Impact on - SAFETY | JL1: =JK1 -> Impact on - SAFETY | JN1: =BQ2 -> Impact on - STATION | JO1: =JN1 -> Impact on - STATION | JP1: =JO1 -> Impact on - STATION | JQ1: =JP1 -> Impact on - STATION | JR1: =JQ1 -> Impact on - STATION | JS1: =JR1 -> Impact on - STATION | JT1: =JS1 -> Impact on - STATION | JU1: =JT1 -> Impact on - STATION | JV1: =JU1 -> Impact on - STATION | JX1: =BR2 -> Impact on - STRAT | JY1: =JX1 -> Impact on - STRAT | JZ1: =JY1 -> Impact on - STRAT | KA1: =JZ1 -> Impact on - STRAT | KB1: =KA1 -> Impact on - STRAT | KC1: =KB1 -> Impact on - STRAT | KD1: =KC1 -> Impact on - STRAT | KE1: =KD1 -> Impact on - STRAT | KF1: =KE1 -> Impact on - STRAT
A2: main 2025 Strategic Pillar 2025 | B2: Status | C2: Team | D2: IS Portfolio Ref ID | E2: Project | F2: eurostar dpt Owner | G2: Starting Date | H2: Level of Certainty on Start Date | I2: Delivery Date | J2: IS 2025 Priority | K2: Duration | L2: Duration Score | M2: #Simplify | N2: Safety | O2: NPS cust. Satisfaction | P2: Punctuality T15 | Q2: People Engagement | R2: EBITDA | S2: Regulatory | T2: Value Score | U2: Column2 | V2: CORPHRFIN | W2: CUST | X2: CYBER | Y2: DATA | Z2: INFRA | AA2: OPERATIONS | AB2: PMO | AC2: SALES | AD2: Number of Team Involved | AE2: Resource Score | AF2: Column3 | AG2: Impact on - CIAL | AH2: Impact on - COM | AI2: Impact on - FIN | AJ2: Impact on - GEN SEC | AK2: Impact on - HR | AL2: Impact on - IS | AM2: Impact on - OPS | AN2: Impact on - ROLL STOCK | AO2: Impact on - SAFETY | AP2: Impact on - STATION | AQ2: Impact on - STRAT | AR2: CHANGE Impact Score | AS2: EFFORT SCORE | AT2: Overall Effort Score | AU2: Ratio - Benefit / Effort | AV2: Project ID | AW2: Name of IS owner | AX2: OK comBoard | AY2: ORACLE/NAV/Fin project code | AZ2: Opex IS Budget (full project) | BA2: Capex IS Budget (full project) | BB2: mainly OPEX or CAPEX | BC2: Total IS Budget (full project) | BD2: Nb IS Employees implicated | BE2: Nb IS Contractors implicated | BH2: =InputTable[[#Headers],[Impact on - CIAL]] -> Impact on - CIAL | BI2: =InputTable[[#Headers],[Impact on - COM]] -> Impact on - COM | BJ2: =InputTable[[#Headers],[Impact on - FIN]] -> Impact on - FIN | BK2: =InputTable[[#Headers],[Impact on - GEN SEC]] -> Impact on - GEN SEC | BL2: =InputTable[[#Headers],[Impact on - HR]] -> Impact on - HR | BM2: =InputTable[[#Headers],[Impact on - IS]] -> Impact on - IS | BN2: =InputTable[[#Headers],[Impact on - OPS]] -> Impact on - OPS | BO2: =InputTable[[#Headers],[Impact on - ROLL STOCK]] -> Impact on - ROLL STOCK | BP2: =InputTable[[#Headers],[Impact on - SAFETY]] -> Impact on - SAFETY | BQ2: =InputTable[[#Headers],[Impact on - STATION]] -> Impact on - STATION | BR2: =InputTable[[#Headers],[Impact on - STRAT]] -> Impact on - STRAT | BT2: =InputTable[[#Headers],[CORPHRFIN]] -> CORPHRFIN | BU2: =InputTable[[#Headers],[CUST]] -> CUST | BV2: =InputTable[[#Headers],[CYBER]] -> CYBER | BW2: =InputTable[[#Headers],[DATA]] -> DATA | BX2: =InputTable[[#Headers],[INFRA]] -> INFRA | BY2: =InputTable[[#Headers],[OPERATIONS]] -> OPERATIONS | BZ2: =InputTable[[#Headers],[PMO]] -> PMO | CA2: =InputTable[[#Headers],[SALES]] -> SALES | CC2: ='System List'!#REF! -> #REF! | CD2: {=TRANSPOSE('System List'!D5:D12)} -> Q4 2024 | CE2: Q1 2025 | CF2: Q2 2025 | CG2: Q3 2025 | CH2: Q4 2025 | CI2: 2026 | CJ2: 2027 | CK2: 2028 + | CN2: ='System List'!#REF! -> #REF! | CO2: ='System List'!$B$5 -> 2024 | CP2: ='System List'!$B$6 -> 2025 Q1 | CQ2: ='System List'!$B$7 -> 2025 Q2 | CR2: ='System List'!$B$8 -> 2025 Q3 | CS2: ='System List'!$B$9 -> 2025 Q4 | CT2: ='System List'!$B$14 -> 2026 Q4 | CU2: ='System List'!$B$15 -> 2027 | CV2: ='System List'!$B$16 -> 2028 + | CX2: ='System List'!#REF! -> #REF! | CY2: ='System List'!$B$5 -> 2024 | CZ2: ='System List'!$B$6 -> 2025 Q1 | DA2: ='System List'!$B$7 -> 2025 Q2 | DB2: ='System List'!$B$8 -> 2025 Q3 | DC2: ='System List'!$B$9 -> 2025 Q4 | DD2: ='System List'!$B$14 -> 2026 Q4 | DE2: ='System List'!$B$15 -> 2027 | DF2: ='System List'!$B$16 -> 2028 + | DH2: ='System List'!#REF! -> #REF! | DI2: ='System List'!$B$5 -> 2024 | DJ2: ='System List'!$B$6 -> 2025 Q1 | DK2: ='System List'!$B$7 -> 2025 Q2 | DL2: ='System List'!$B$8 -> 2025 Q3 | DM2: ='System List'!$B$9 -> 2025 Q4 | DN2: ='System List'!$B$14 -> 2026 Q4 | DO2: ='System List'!$B$15 -> 2027 | DP2: ='System List'!$B$16 -> 2028 + | DR2: ='System List'!#REF! -> #REF! | DS2: ='System List'!$B$5 -> 2024 | DT2: ='System List'!$B$6 -> 2025 Q1 | DU2: ='System List'!$B$7 -> 2025 Q2 | DV2: ='System List'!$B$8 -> 2025 Q3 | DW2: ='System List'!$B$9 -> 2025 Q4 | DX2: ='System List'!$B$14 -> 2026 Q4 | DY2: ='System List'!$B$15 -> 2027 | DZ2: ='System List'!$B$16 -> 2028 + | EB2: ='System List'!#REF! -> #REF! | EC2: ='System List'!$B$5 -> 2024 | ED2: ='System List'!$B$6 -> 2025 Q1 | EE2: ='System List'!$B$7 -> 2025 Q2 | EF2: ='System List'!$B$8 -> 2025 Q3 | EG2: ='System List'!$B$9 -> 2025 Q4 | EH2: ='System List'!$B$14 -> 2026 Q4 | EI2: ='System List'!$B$15 -> 2027 | EJ2: ='System List'!$B$16 -> 2028 + | EL2: ='System List'!#REF! -> #REF! | EM2: ='System List'!$B$5 -> 2024 | EN2: ='System List'!$B$6 -> 2025 Q1 | EO2: ='System List'!$B$7 -> 2025 Q2 | EP2: ='System List'!$B$8 -> 2025 Q3 | EQ2: ='System List'!$B$9 -> 2025 Q4 | ER2: ='System List'!$B$14 -> 2026 Q4 | ES2: ='System List'!$B$15 -> 2027 | ET2: ='System List'!$B$16 -> 2028 + | EV2: ='System List'!#REF! -> #REF! | EW2: ='System List'!$B$5 -> 2024 | EX2: ='System List'!$B$6 -> 2025 Q1 | EY2: ='System List'!$B$7 -> 2025 Q2 | EZ2: ='System List'!$B$8 -> 2025 Q3 | FA2: ='System List'!$B$9 -> 2025 Q4 | FB2: ='System List'!$B$14 -> 2026 Q4 | FC2: ='System List'!$B$15 -> 2027 | FD2: ='System List'!$B$16 -> 2028 + | FF2: ='System List'!#REF! -> #REF! | FG2: ='System List'!$B$5 -> 2024 | FH2: ='System List'!$B$6 -> 2025 Q1 | FI2: ='System List'!$B$7 -> 2025 Q2 | FJ2: ='System List'!$B$8 -> 2025 Q3 | FK2: ='System List'!$B$9 -> 2025 Q4 | FL2: ='System List'!$B$14 -> 2026 Q4 | FM2: ='System List'!$B$15 -> 2027 | FN2: ='System List'!$B$16 -> 2028 + | FP2: ='System List'!#REF! -> #REF! | FQ2: ='System List'!$B$5 -> 2024 | FR2: ='System List'!$B$6 -> 2025 Q1 | FS2: ='System List'!$B$7 -> 2025 Q2 | FT2: ='System List'!$B$8 -> 2025 Q3 | FU2: ='System List'!$B$9 -> 2025 Q4 | FV2: ='System List'!$B$14 -> 2026 Q4 | FW2: ='System List'!$B$15 -> 2027 | FX2: ='System List'!$B$16 -> 2028 + | GB2: ='System List'!#REF! -> #REF! | GC2: ='System List'!$B$5 -> 2024 | GD2: ='System List'!$B$6 -> 2025 Q1 | GE2: ='System List'!$B$7 -> 2025 Q2 | GF2: ='System List'!$B$8 -> 2025 Q3 | GG2: ='System List'!$B$9 -> 2025 Q4 | GH2: ='System List'!$B$14 -> 2026 Q4 | GI2: ='System List'!$B$15 -> 2027 | GJ2: ='System List'!$B$16 -> 2028 + | GL2: ='System List'!#REF! -> #REF! | GM2: ='System List'!$B$5 -> 2024 | GN2: ='System List'!$B$6 -> 2025 Q1 | GO2: ='System List'!$B$7 -> 2025 Q2 | GP2: ='System List'!$B$8 -> 2025 Q3 | GQ2: ='System List'!$B$9 -> 2025 Q4 | GR2: ='System List'!$B$14 -> 2026 Q4 | GS2: ='System List'!$B$15 -> 2027 | GT2: ='System List'!$B$16 -> 2028 + | GV2: ='System List'!#REF! -> #REF! | GW2: ='System List'!$B$5 -> 2024 | GX2: ='System List'!$B$6 -> 2025 Q1 | GY2: ='System List'!$B$7 -> 2025 Q2 | GZ2: ='System List'!$B$8 -> 2025 Q3 | HA2: ='System List'!$B$9 -> 2025 Q4 | HB2: ='System List'!$B$14 -> 2026 Q4 | HC2: ='System List'!$B$15 -> 2027 | HD2: ='System List'!$B$16 -> 2028 + | HF2: ='System List'!#REF! -> #REF! | HG2: ='System List'!$B$5 -> 2024 | HH2: ='System List'!$B$6 -> 2025 Q1 | HI2: ='System List'!$B$7 -> 2025 Q2 | HJ2: ='System List'!$B$8 -> 2025 Q3 | HK2: ='System List'!$B$9 -> 2025 Q4 | HL2: ='System List'!$B$14 -> 2026 Q4 | HM2: ='System List'!$B$15 -> 2027 | HN2: ='System List'!$B$16 -> 2028 + | HP2: ='System List'!#REF! -> #REF! | HQ2: ='System List'!$B$5 -> 2024 | HR2: ='System List'!$B$6 -> 2025 Q1 | HS2: ='System List'!$B$7 -> 2025 Q2 | HT2: ='System List'!$B$8 -> 2025 Q3 | HU2: ='System List'!$B$9 -> 2025 Q4 | HV2: ='System List'!$B$14 -> 2026 Q4 | HW2: ='System List'!$B$15 -> 2027 | HX2: ='System List'!$B$16 -> 2028 + | HZ2: ='System List'!#REF! -> #REF! | IA2: ='System List'!$B$5 -> 2024 | IB2: ='System List'!$B$6 -> 2025 Q1 | IC2: ='System List'!$B$7 -> 2025 Q2 | ID2: ='System List'!$B$8 -> 2025 Q3 | IE2: ='System List'!$B$9 -> 2025 Q4 | IF2: ='System List'!$B$14 -> 2026 Q4 | IG2: ='System List'!$B$15 -> 2027 | IH2: ='System List'!$B$16 -> 2028 + | IJ2: ='System List'!#REF! -> #REF! | IK2: ='System List'!$B$5 -> 2024 | IL2: ='System List'!$B$6 -> 2025 Q1 | IM2: ='System List'!$B$7 -> 2025 Q2 | IN2: ='System List'!$B$8 -> 2025 Q3 | IO2: ='System List'!$B$9 -> 2025 Q4 | IP2: ='System List'!$B$14 -> 2026 Q4 | IQ2: ='System List'!$B$15 -> 2027 | IR2: ='System List'!$B$16 -> 2028 + | IT2: ='System List'!#REF! -> #REF! | IU2: ='System List'!$B$5 -> 2024 | IV2: ='System List'!$B$6 -> 2025 Q1 | IW2: ='System List'!$B$7 -> 2025 Q2 | IX2: ='System List'!$B$8 -> 2025 Q3 | IY2: ='System List'!$B$9 -> 2025 Q4 | IZ2: ='System List'!$B$14 -> 2026 Q4 | JA2: ='System List'!$B$15 -> 2027 | JB2: ='System List'!$B$16 -> 2028 + | JD2: ='System List'!#REF! -> #REF! | JE2: ='System List'!$B$5 -> 2024 | JF2: ='System List'!$B$6 -> 2025 Q1 | JG2: ='System List'!$B$7 -> 2025 Q2 | JH2: ='System List'!$B$8 -> 2025 Q3 | JI2: ='System List'!$B$9 -> 2025 Q4 | JJ2: ='System List'!$B$14 -> 2026 Q4 | JK2: ='System List'!$B$15 -> 2027 | JL2: ='System List'!$B$16 -> 2028 + | JN2: ='System List'!#REF! -> #REF! | JO2: ='System List'!$B$5 -> 2024 | JP2: ='System List'!$B$6 -> 2025 Q1 | JQ2: ='System List'!$B$7 -> 2025 Q2 | JR2: ='System List'!$B$8 -> 2025 Q3 | JS2: ='System List'!$B$9 -> 2025 Q4 | JT2: ='System List'!$B$14 -> 2026 Q4 | JU2: ='System List'!$B$15 -> 2027 | JV2: ='System List'!$B$16 -> 2028 + | JX2: ='System List'!#REF! -> #REF! | JY2: ='System List'!$B$5 -> 2024 | JZ2: ='System List'!$B$6 -> 2025 Q1 | KA2: ='System List'!$B$7 -> 2025 Q2 | KB2: ='System List'!$B$8 -> 2025 Q3 | KC2: ='System List'!$B$9 -> 2025 Q4 | KD2: ='System List'!$B$14 -> 2026 Q4 | KE2: ='System List'!$B$15 -> 2027 | KF2: ='System List'!$B$16 -> 2028 +
B3: Complete | C3: DIGITAL TECH | D3: ISPRJ-1 | E3: Digital Roadmap 2025 (Increase website and app conversion + indirect sales) | F3: COMMERCIAL | G3: 2025 Q1 | I3: 2025 Q4 | J3: TOP10 $$$ | K3: =VLOOKUP((InputTable[[#This Row],[Starting Date]]& " - " &InputTable[[#This Row],[Delivery Date]]),'System List'!$F$40:$H$83,2,FALSE) -> #N/A | L3: =VLOOKUP(InputTable[[#This Row],[Duration]],Duration,2,FALSE) -> #N/A | O3: H | R3: H | T3: {=SUM( _xlfn.XLOOKUP(InputTable[[#This Row],[Safety]:[Regulatory]], 'System List'!$F$4:$F$7, 'System List'!$G$4:$G$7, 0) * _xlfn.XLOOKUP(InputTable[[#Headers],[Safety]:[Regulatory]], 'System List'!$Y$4:$Y$10, 'System List'!$Z$4:$Z$10, 0) )} -> 6.5 | AD3: =COUNTA(InputTable[[#This Row],[CORPHRFIN]:[SALES]]) -> 0 | AE3: {=SUM( _xlfn.XLOOKUP(InputTable[[#This Row],[CORPHRFIN]:[SALES]],'System List'!$F$4:$F$7,'System List'!$H$4:$H$7,0))} -> 0 | AR3: {=SUM( _xlfn.XLOOKUP(InputTable[[#This Row],[Impact on - CIAL]:[Impact on - STRAT]],'System List'!$F$4:$F$7,'System List'!$H$4:$H$7,0))} -> 0 | AS3: =VLOOKUP(InputTable[[#This Row],[Duration]],Duration,2,FALSE)+InputTable[[#This Row],[Resource Score]] -> #N/A | AT3: =(( VLOOKUP(InputTable[[#This Row],[Duration]],'System List'!$J$5:$K$10,2,FALSE)*VLOOKUP(InputTable[[#Headers],[Duration]],'System List'!$V$5:$W$8,2,FALSE) + VLOOKUP(InputTable[[#This Row],[Number of Team Involved]],'System List'!$M$5:$N$13,2,FALSE)*VLOOKUP(InputTable[[#Headers],[Number of Team Involved]],'System List'!$V$5:$W$8,2,FALSE) + VLOOKUP(InputTable[[#This Row],[Resource Score]],Resource_Score,2,FALSE)*VLOOKUP(InputTable[[#Headers],[Resource Score]],'System List'!$V$5:$W$8,2,FALSE) + VLOOKUP(InputTable[[#This Row],[CHANGE Impact Score]],CHANGE_Impact_Score,2,FALSE)*VLOOKUP(InputTable[[#Headers],[CHANGE Impact Score]],'System List'!$V$5:$W$8,2,FALSE)) * 100) / 13 -> #N/A | AU3: =InputTable[[#This Row],[Value Score]]/InputTable[[#This Row],[EFFORT SCORE]]*100 -> #N/A | AV3: =InputTable[[#This Row],[IS Portfolio Ref ID]] -> ISPRJ-1 | AW3: Xavier ROMANET | AX3: approved in Digital BC | AY3: 1840 | BA3: =9500000*$BA$1 -> 10795800 | BB3: full CAPEX | BC3: =InputTable[[#This Row],[Capex IS Budget (full project)]]+InputTable[[#This Row],[Opex IS Budget (full project)]] -> 10795800 | BD3: 18 | BE3: 76 | BH3: =IFERROR(VLOOKUP(InputTable[[#This Row],[Impact on - CIAL]],'System List'!$F$4:$H$7,3,FALSE),0) -> 0 | BI3: =IFERROR(VLOOKUP(InputTable[[#This Row],[Impact on - COM]],'System List'!$F$4:$H$7,3,FALSE),0) -> 0 | BJ3: =IFERROR(VLOOKUP(InputTable[[#This Row],[Impact on - FIN]],'System List'!$F$4:$H$7,3,FALSE),0) -> 0 | BK3: =IFERROR(VLOOKUP(InputTable[[#This Row],[Impact on - GEN SEC]],'System List'!$F$4:$H$7,3,FALSE),0) -> 0 | BL3: =IFERROR(VLOOKUP(InputTable[[#This Row],[Impact on - HR]],'System List'!$F$4:$H$7,3,FALSE),0) -> 0 | BM3: =IFERROR(VLOOKUP(InputTable[[#This Row],[Impact on - IS]],'System List'!$F$4:$H$7,3,FALSE),0) -> 0 | BN3: =IFERROR(VLOOKUP(InputTable[[#This Row],[Impact on - OPS]],'System List'!$F$4:$H$7,3,FALSE),0) -> 0 | BO3: =IFERROR(VLOOKUP(InputTable[[#This Row],[Impact on - ROLL STOCK]],'System List'!$F$4:$H$7,3,FALSE),0) -> 0 | BP3: =IFERROR(VLOOKUP(InputTable[[#This Row],[Impact on - SAFETY]],'System List'!$F$4:$H$7,3,FALSE),0) -> 0 | BQ3: =IFERROR(VLOOKUP(InputTable[[#This Row],[Impact on - STATION]],'System List'!$F$4:$H$7,3,FALSE),0) -> 0 | BR3: =IFERROR(VLOOKUP(InputTable[[#This Row],[Impact on - STRAT]],'System List'!$F$4:$H$7,3,FALSE),0) -> 0 | BT3: =IFERROR(VLOOKUP(InputTable[[#This Row],[CORPHRFIN]],'System List'!$F$4:$H$7,3,FALSE),0) -> 0 | BU3: =IFERROR(VLOOKUP(InputTable[[#This Row],[CUST]],'System List'!$F$4:$H$7,3,FALSE),0) -> 0 | BV3: =IFERROR(VLOOKUP(InputTable[[#This Row],[CYBER]],'System List'!$F$4:$H$7,3,FALSE),0) -> 0 | BW3: =IFERROR(VLOOKUP(InputTable[[#This Row],[DATA]],'System List'!$F$4:$H$7,3,FALSE),0) -> 0 | BX3: =IFERROR(VLOOKUP(InputTable[[#This Row],[INFRA]],'System List'!$F$4:$H$7,3,FALSE),0) -> 0 | BY3: =IFERROR(VLOOKUP(InputTable[[#This Row],[OPERATIONS]],'System List'!$F$4:$H$7,3,FALSE),0) -> 0 | BZ3: =IFERROR(VLOOKUP(InputTable[[#This Row],[PMO]],'System List'!$F$4:$H$7,3,FALSE),0) -> 0 | CA3: =IFERROR(VLOOKUP(InputTable[[#This Row],[SALES]],'System List'!$F$4:$H$7,3,FALSE),0) -> 0 | CC3: {=IFERROR( IF( AND( MATCH(InputTable[[#This Row],[Starting Date]],'System List'!$B$5:$B$16,0)<=MATCH(Input!CC$2,'System List'!$B$5:$B$16,0), MATCH(Input!CC$2,'System List'!$B$5:$B$16<=MATCH(InputTable[[#This Row],[Delivery Date]],'System List'!$B$5:$B$16,0))),1,0), )} -> 0 | CD3: {=IFERROR( IF( AND( MATCH(InputTable[[#This Row],[Starting Date]],'System List'!$B$5:$B$16,0)<=MATCH(Input!CD$2,'System List'!$B$5:$B$16,0), MATCH(Input!CD$2,'System List'!$B$5:$B$16<=MATCH(InputTable[[#This Row],[Delivery Date]],'System List'!$B$5:$B$16,0))),1,0), )} -> 0 | CE3: {=IFERROR( IF( AND( MATCH(InputTable[[#This Row],[Starting Date]],'System List'!$B$5:$B$16,0)<=MATCH(Input!CE$2,'System List'!$B$5:$B$16,0), MATCH(Input!CE$2,'System List'!$B$5:$B$16<=MATCH(InputTable[[#This Row],[Delivery Date]],'System List'!$B$5:$B$16,0))),1,0), )} -> 0 | CF3: {=IFERROR( IF( AND( MATCH(InputTable[[#This Row],[Starting Date]],'System List'!$B$5:$B$16,0)<=MATCH(Input!CF$2,'System List'!$B$5:$B$16,0), MATCH(Input!CF$2,'System List'!$B$5:$B$16<=MATCH(InputTable[[#This Row],[Delivery Date]],'System List'!$B$5:$B$16,0))),1,0), )} -> 0 | CG3: {=IFERROR( IF( AND( MATCH(InputTable[[#This Row],[Starting Date]],'System List'!$B$5:$B$16,0)<=MATCH(Input!CG$2,'System List'!$B$5:$B$16,0), MATCH(Input!CG$2,'System List'!$B$5:$B$16<=MATCH(InputTable[[#This Row],[Delivery Date]],'System List'!$B$5:$B$16,0))),1,0), )} -> 0 | CH3: {=IFERROR( IF( AND( MATCH(InputTable[[#This Row],[Starting Date]],'System List'!$B$5:$B$16,0)<=MATCH(Input!CH$2,'System List'!$B$5:$B$16,0), MATCH(Input!CH$2,'System List'!$B$5:$B$16<=MATCH(InputTable[[#This Row],[Delivery Date]],'System List'!$B$5:$B$16,0))),1,0), )} -> 0 | CI3: {=IFERROR( IF( AND( MATCH(InputTable[[#This Row],[Starting Date]],'System List'!$B$5:$B$16,0)<=MATCH(Input!CI$2,'System List'!$B$5:$B$16,0), MATCH(Input!CI$2,'System List'!$B$5:$B$16<=MATCH(InputTable[[#This Row],[Delivery Date]],'System List'!$B$5:$B$16,0))),1,0), )} -> 0 | CJ3: {=IFERROR( IF( AND( MATCH(InputTable[[#This Row],[Starting Date]],'System List'!$B$5:$B$16,0)<=MATCH(Input!CJ$2,'System List'!$B$5:$B$16,0), MATCH(Input!CJ$2,'System List'!$B$5:$B$16<=MATCH(InputTable[[#This Row],[Delivery Date]],'System List'!$B$5:$B$16,0))),1,0), )} -> 0 | CK3: {=IFERROR( IF( AND( MATCH(InputTable[[#This Row],[Starting Date]],'System List'!$B$5:$B$16,0)<=MATCH(Input!CK$2,'System List'!$B$5:$B$16,0), MATCH(Input!CK$2,'System List'!$B$5:$B$16<=MATCH(InputTable[[#This Row],[Delivery Date]],'System List'!$B$5:$B$16,0))),1,0), )} -> 0 | CN3: =IFERROR( IF(AND( MATCH(InputTable[[#This Row],[Starting Date]],'System List'!$B$5:$B$16,0)<=MATCH(CN$2,'System List'!$B$5:$B$16,0), MATCH(CN$2,'System List'!$B$5:$B$16,0)<=MATCH(InputTable[[#This Row],[Delivery Date]],'System List'!$B$5:$B$16,0)),1,0),0) -> 0 | CO3: =IFERROR( IF(AND( MATCH(InputTable[[#This Row],[Starting Date]],'System List'!$B$5:$B$16,0)<=MATCH(CO$2,'System List'!$B$5:$B$16,0), MATCH(CO$2,'System List'!$B$5:$B$16,0)<=MATCH(InputTable[[#This Row],[Delivery Date]],'System List'!$B$5:$B$16,0)),1,0),0) -> 0 | CP3: =IFERROR( IF(AND( MATCH(InputTable[[#This Row],[Starting Date]],'System List'!$B$5:$B$16,0)<=MATCH(CP$2,'System List'!$B$5:$B$16,0), MATCH(CP$2,'System List'!$B$5:$B$16,0)<=MATCH(InputTable[[#This Row],[Delivery Date]],'System List'!$B$5:$B$16,0)),1,0),0) -> 1 | CQ3: =IFERROR( IF(AND( MATCH(InputTable[[#This Row],[Starting Date]],'System List'!$B$5:$B$16,0)<=MATCH(CQ$2,'System List'!$B$5:$B$16,0), MATCH(CQ$2,'System List'!$B$5:$B$16,0)<=MATCH(InputTable[[#This Row],[Delivery Date]],'System List'!$B$5:$B$16,0)),1,0),0) -> 1 | CR3: =IFERROR( IF(AND( MATCH(InputTable[[#This Row],[Starting Date]],'System List'!$B$5:$B$16,0)<=MATCH(CR$2,'System List'!$B$5:$B$16,0), MATCH(CR$2,'System List'!$B$5:$B$16,0)<=MATCH(InputTable[[#This Row],[Delivery Date]],'System List'!$B$5:$B$16,0)),1,0),0) -> 1 | CS3: =IFERROR( IF(AND( MATCH(InputTable[[#This Row],[Starting Date]],'System List'!$B$5:$B$16,0)<=MATCH(CS$2,'System List'!$B$5:$B$16,0), MATCH(CS$2,'System List'!$B$5:$B$16,0)<=MATCH(InputTable[[#This Row],[Delivery Date]],'System List'!$B$5:$B$16,0)),1,0),0) -> 1 | CT3: =IFERROR( IF(AND( MATCH(InputTable[[#This Row],[Starting Date]],'System List'!$B$5:$B$16,0)<=MATCH(CT$2,'System List'!$B$5:$B$16,0), MATCH(CT$2,'System List'!$B$5:$B$16,0)<=MATCH(InputTable[[#This Row],[Delivery Date]],'System List'!$B$5:$B$16,0)),1,0),0) -> 0 | CU3: =IFERROR( IF(AND( MATCH(InputTable[[#This Row],[Starting Date]],'System List'!$B$5:$B$16,0)<=MATCH(CU$2,'System List'!$B$5:$B$16,0), MATCH(CU$2,'System List'!$B$5:$B$16,0)<=MATCH(InputTable[[#This Row],[Delivery Date]],'System List'!$B$5:$B$16,0)),1,0),0) -> 0 | CV3: =IFERROR( IF(AND( MATCH(InputTable[[#This Row],[Starting Date]],'System List'!$B$5:$B$16,0)<=MATCH(CV$2,'System List'!$B$5:$B$16,0), MATCH(CV$2,'System List'!$B$5:$B$16,0)<=MATCH(InputTable[[#This Row],[Delivery Date]],'System List'!$B$5:$B$16,0)),1,0),0) -> 0 | CX3: =$CN3*_xlfn.XLOOKUP(CX$1,$BT$2:$CA$2,$BT3:$CA3,0) -> 0 | CY3: =$CO3*_xlfn.XLOOKUP(CY$1,$BT$2:$CA$2,$BT3:$CA3,0) -> 0 | CZ3: =$CP3*_xlfn.XLOOKUP(CZ$1,$BT$2:$CA$2,$BT3:$CA3,0) -> 0 | DA3: =$CQ3*_xlfn.XLOOKUP(DA$1,$BT$2:$CA$2,$BT3:$CA3,0) -> 0 | DB3: =$CR3*_xlfn.XLOOKUP(DB$1,$BT$2:$CA$2,$BT3:$CA3,0) -> 0 | DC3: =$CS3*_xlfn.XLOOKUP(DC$1,$BT$2:$CA$2,$BT3:$CA3,0) -> 0 | DD3: =$CT3*_xlfn.XLOOKUP(DD$1,$BT$2:$CA$2,$BT3:$CA3,0) -> 0 | DE3: =$CU3*_xlfn.XLOOKUP(DE$1,$BT$2:$CA$2,$BT3:$CA3,0) -> 0 | DF3: =$CV3*_xlfn.XLOOKUP(DF$1,$BT$2:$CA$2,$BT3:$CA3,0) -> 0 | DH3: =$CN3*_xlfn.XLOOKUP(DH$1,$BT$2:$CA$2,$BT3:$CA3,0) -> 0 | DI3: =$CO3*_xlfn.XLOOKUP(DI$1,$BT$2:$CA$2,$BT3:$CA3,0) -> 0 | DJ3: =$CP3*_xlfn.XLOOKUP(DJ$1,$BT$2:$CA$2,$BT3:$CA3,0) -> 0 | DK3: =$CQ3*_xlfn.XLOOKUP(DK$1,$BT$2:$CA$2,$BT3:$CA3,0) -> 0 | DL3: =$CR3*_xlfn.XLOOKUP(DL$1,$BT$2:$CA$2,$BT3:$CA3,0) -> 0 | DM3: =$CS3*_xlfn.XLOOKUP(DM$1,$BT$2:$CA$2,$BT3:$CA3,0) -> 0 | DN3: =$CT3*_xlfn.XLOOKUP(DN$1,$BT$2:$CA$2,$BT3:$CA3,0) -> 0 | DO3: =$CU3*_xlfn.XLOOKUP(DO$1,$BT$2:$CA$2,$BT3:$CA3,0) -> 0 | DP3: =$CV3*_xlfn.XLOOKUP(DP$1,$BT$2:$CA$2,$BT3:$CA3,0) -> 0 | DR3: =$CN3*_xlfn.XLOOKUP(DR$1,$BT$2:$CA$2,$BT3:$CA3,0) -> 0 | DS3: =$CO3*_xlfn.XLOOKUP(DS$1,$BT$2:$CA$2,$BT3:$CA3,0) -> 0 | DT3: =$CP3*_xlfn.XLOOKUP(DT$1,$BT$2:$CA$2,$BT3:$CA3,0) -> 0 | DU3: =$CQ3*_xlfn.XLOOKUP(DU$1,$BT$2:$CA$2,$BT3:$CA3,0) -> 0 | DV3: =$CR3*_xlfn.XLOOKUP(DV$1,$BT$2:$CA$2,$BT3:$CA3,0) -> 0 | DW3: =$CS3*_xlfn.XLOOKUP(DW$1,$BT$2:$CA$2,$BT3:$CA3,0) -> 0 | DX3: =$CT3*_xlfn.XLOOKUP(DX$1,$BT$2:$CA$2,$BT3:$CA3,0) -> 0 | DY3: =$CU3*_xlfn.XLOOKUP(DY$1,$BT$2:$CA$2,$BT3:$CA3,0) -> 0 | DZ3: =$CV3*_xlfn.XLOOKUP(DZ$1,$BT$2:$CA$2,$BT3:$CA3,0) -> 0 | EB3: =$CN3*_xlfn.XLOOKUP(EB$1,$BT$2:$CA$2,$BT3:$CA3,0) -> 0 | EC3: =$CO3*_xlfn.XLOOKUP(EC$1,$BT$2:$CA$2,$BT3:$CA3,0) -> 0 | ED3: =$CP3*_xlfn.XLOOKUP(ED$1,$BT$2:$CA$2,$BT3:$CA3,0) -> 0 | EE3: =$CQ3*_xlfn.XLOOKUP(EE$1,$BT$2:$CA$2,$BT3:$CA3,0) -> 0 | EF3: =$CR3*_xlfn.XLOOKUP(EF$1,$BT$2:$CA$2,$BT3:$CA3,0) -> 0 | EG3: =$CS3*_xlfn.XLOOKUP(EG$1,$BT$2:$CA$2,$BT3:$CA3,0) -> 0 | EH3: =$CT3*_xlfn.XLOOKUP(EH$1,$BT$2:$CA$2,$BT3:$CA3,0) -> 0 | EI3: =$CU3*_xlfn.XLOOKUP(EI$1,$BT$2:$CA$2,$BT3:$CA3,0) -> 0 | EJ3: =$CV3*_xlfn.XLOOKUP(EJ$1,$BT$2:$CA$2,$BT3:$CA3,0) -> 0 | EL3: =$CN3*_xlfn.XLOOKUP(EL$1,$BT$2:$CA$2,$BT3:$CA3,0) -> 0 | EM3: =$CO3*_xlfn.XLOOKUP(EM$1,$BT$2:$CA$2,$BT3:$CA3,0) -> 0 | EN3: =$CP3*_xlfn.XLOOKUP(EN$1,$BT$2:$CA$2,$BT3:$CA3,0) -> 0 | EO3: =$CQ3*_xlfn.XLOOKUP(EO$1,$BT$2:$CA$2,$BT3:$CA3,0) -> 0 | EP3: =$CR3*_xlfn.XLOOKUP(EP$1,$BT$2:$CA$2,$BT3:$CA3,0) -> 0 | EQ3: =$CS3*_xlfn.XLOOKUP(EQ$1,$BT$2:$CA$2,$BT3:$CA3,0) -> 0 | ER3: =$CT3*_xlfn.XLOOKUP(ER$1,$BT$2:$CA$2,$BT3:$CA3,0) -> 0 | ES3: =$CU3*_xlfn.XLOOKUP(ES$1,$BT$2:$CA$2,$BT3:$CA3,0) -> 0 | ET3: =$CV3*_xlfn.XLOOKUP(ET$1,$BT$2:$CA$2,$BT3:$CA3,0) -> 0 | EV3: =$CN3*_xlfn.XLOOKUP(EV$1,$BT$2:$CA$2,$BT3:$CA3,0) -> 0 | EW3: =$CO3*_xlfn.XLOOKUP(EW$1,$BT$2:$CA$2,$BT3:$CA3,0) -> 0 | EX3: =$CP3*_xlfn.XLOOKUP(EX$1,$BT$2:$CA$2,$BT3:$CA3,0) -> 0 | EY3: =$CQ3*_xlfn.XLOOKUP(EY$1,$BT$2:$CA$2,$BT3:$CA3,0) -> 0 | EZ3: =$CR3*_xlfn.XLOOKUP(EZ$1,$BT$2:$CA$2,$BT3:$CA3,0) -> 0 | FA3: =$CS3*_xlfn.XLOOKUP(FA$1,$BT$2:$CA$2,$BT3:$CA3,0) -> 0 | FB3: =$CT3*_xlfn.XLOOKUP(FB$1,$BT$2:$CA$2,$BT3:$CA3,0) -> 0 | FC3: =$CU3*_xlfn.XLOOKUP(FC$1,$BT$2:$CA$2,$BT3:$CA3,0) -> 0 | FD3: =$CV3*_xlfn.XLOOKUP(FD$1,$BT$2:$CA$2,$BT3:$CA3,0) -> 0 | FF3: =$CN3*_xlfn.XLOOKUP(FF$1,$BT$2:$CA$2,$BT3:$CA3,0) -> 0 | FG3: =$CO3*_xlfn.XLOOKUP(FG$1,$BT$2:$CA$2,$BT3:$CA3,0) -> 0 | FH3: =$CP3*_xlfn.XLOOKUP(FH$1,$BT$2:$CA$2,$BT3:$CA3,0) -> 0 | FI3: =$CQ3*_xlfn.XLOOKUP(FI$1,$BT$2:$CA$2,$BT3:$CA3,0) -> 0 | FJ3: =$CR3*_xlfn.XLOOKUP(FJ$1,$BT$2:$CA$2,$BT3:$CA3,0) -> 0 | FK3: =$CS3*_xlfn.XLOOKUP(FK$1,$BT$2:$CA$2,$BT3:$CA3,0) -> 0 | FL3: =$CT3*_xlfn.XLOOKUP(FL$1,$BT$2:$CA$2,$BT3:$CA3,0) -> 0 | FM3: =$CU3*_xlfn.XLOOKUP(FM$1,$BT$2:$CA$2,$BT3:$CA3,0) -> 0 | FN3: =$CV3*_xlfn.XLOOKUP(FN$1,$BT$2:$CA$2,$BT3:$CA3,0) -> 0 | FP3: =$CN3*_xlfn.XLOOKUP(FP$1,$BT$2:$CA$2,$BT3:$CA3,0) -> #REF! | FQ3: =$CO3*_xlfn.XLOOKUP(FQ$1,$BT$2:$CA$2,$BT3:$CA3,0) -> #REF! | FR3: =$CP3*_xlfn.XLOOKUP(FR$1,$BT$2:$CA$2,$BT3:$CA3,0) -> #REF! | FS3: =$CQ3*_xlfn.XLOOKUP(FS$1,$BT$2:$CA$2,$BT3:$CA3,0) -> #REF! | FT3: =$CR3*_xlfn.XLOOKUP(FT$1,$BT$2:$CA$2,$BT3:$CA3,0) -> #REF! | FU3: =$CS3*_xlfn.XLOOKUP(FU$1,$BT$2:$CA$2,$BT3:$CA3,0) -> #REF! | FV3: =$CT3*_xlfn.XLOOKUP(FV$1,$BT$2:$CA$2,$BT3:$CA3,0) -> #REF! | FW3: =$CU3*_xlfn.XLOOKUP(FW$1,$BT$2:$CA$2,$BT3:$CA3,0) -> #REF! | FX3: =$CV3*_xlfn.XLOOKUP(FX$1,$BT$2:$CA$2,$BT3:$CA3,0) -> #REF! | GB3: =IF(GB$2=InputTable[[#This Row],[Delivery Date]],_xlfn.XLOOKUP(GB$1,$BH$2:$BR$2,$BH3:$BR3,0),0) -> #REF! | GC3: =IF(GC$2=InputTable[[#This Row],[Delivery Date]],_xlfn.XLOOKUP(GC$1,$BH$2:$BR$2,$BH3:$BR3,0),0) -> 0 | GD3: =IF(GD$2=InputTable[[#This Row],[Delivery Date]],_xlfn.XLOOKUP(GD$1,$BH$2:$BR$2,$BH3:$BR3,0),0) -> 0 | GE3: =IF(GE$2=InputTable[[#This Row],[Delivery Date]],_xlfn.XLOOKUP(GE$1,$BH$2:$BR$2,$BH3:$BR3,0),0) -> 0 | GF3: =IF(GF$2=InputTable[[#This Row],[Delivery Date]],_xlfn.XLOOKUP(GF$1,$BH$2:$BR$2,$BH3:$BR3,0),0) -> 0 | GG3: =IF(GG$2=InputTable[[#This Row],[Delivery Date]],_xlfn.XLOOKUP(GG$1,$BH$2:$BR$2,$BH3:$BR3,0),0) -> 0 | GH3: =IF(GH$2=InputTable[[#This Row],[Delivery Date]],_xlfn.XLOOKUP(GH$1,$BH$2:$BR$2,$BH3:$BR3,0),0) -> 0 | GI3: =IF(GI$2=InputTable[[#This Row],[Delivery Date]],_xlfn.XLOOKUP(GI$1,$BH$2:$BR$2,$BH3:$BR3,0),0) -> 0 | GJ3: =IF(GJ$2=InputTable[[#This Row],[Delivery Date]],_xlfn.XLOOKUP(GJ$1,$BH$2:$BR$2,$BH3:$BR3,0),0) -> 0 | GL3: =IF(GL$2=InputTable[[#This Row],[Delivery Date]],_xlfn.XLOOKUP(GL$1,$BH$2:$BR$2,$BH3:$BR3,0),0) -> #REF! | GM3: =IF(GM$2=InputTable[[#This Row],[Delivery Date]],_xlfn.XLOOKUP(GM$1,$BH$2:$BR$2,$BH3:$BR3,0),0) -> 0 | GN3: =IF(GN$2=InputTable[[#This Row],[Delivery Date]],_xlfn.XLOOKUP(GN$1,$BH$2:$BR$2,$BH3:$BR3,0),0) -> 0 | GO3: =IF(GO$2=InputTable[[#This Row],[Delivery Date]],_xlfn.XLOOKUP(GO$1,$BH$2:$BR$2,$BH3:$BR3,0),0) -> 0 | GP3: =IF(GP$2=InputTable[[#This Row],[Delivery Date]],_xlfn.XLOOKUP(GP$1,$BH$2:$BR$2,$BH3:$BR3,0),0) -> 0 | GQ3: =IF(GQ$2=InputTable[[#This Row],[Delivery Date]],_xlfn.XLOOKUP(GQ$1,$BH$2:$BR$2,$BH3:$BR3,0),0) -> 0 | GR3: =IF(GR$2=InputTable[[#This Row],[Delivery Date]],_xlfn.XLOOKUP(GR$1,$BH$2:$BR$2,$BH3:$BR3,0),0) -> 0 | GS3: =IF(GS$2=InputTable[[#This Row],[Delivery Date]],_xlfn.XLOOKUP(GS$1,$BH$2:$BR$2,$BH3:$BR3,0),0) -> 0 | GT3: =IF(GT$2=InputTable[[#This Row],[Delivery Date]],_xlfn.XLOOKUP(GT$1,$BH$2:$BR$2,$BH3:$BR3,0),0) -> 0 | GV3: =IF(GV$2=InputTable[[#This Row],[Delivery Date]],_xlfn.XLOOKUP(GV$1,$BH$2:$BR$2,$BH3:$BR3,0),0) -> #REF! | GW3: =IF(GW$2=InputTable[[#This Row],[Delivery Date]],_xlfn.XLOOKUP(GW$1,$BH$2:$BR$2,$BH3:$BR3,0),0) -> 0 | GX3: =IF(GX$2=InputTable[[#This Row],[Delivery Date]],_xlfn.XLOOKUP(GX$1,$BH$2:$BR$2,$BH3:$BR3,0),0) -> 0 | GY3: =IF(GY$2=InputTable[[#This Row],[Delivery Date]],_xlfn.XLOOKUP(GY$1,$BH$2:$BR$2,$BH3:$BR3,0),0) -> 0 | GZ3: =IF(GZ$2=InputTable[[#This Row],[Delivery Date]],_xlfn.XLOOKUP(GZ$1,$BH$2:$BR$2,$BH3:$BR3,0),0) -> 0 | HA3: =IF(HA$2=InputTable[[#This Row],[Delivery Date]],_xlfn.XLOOKUP(HA$1,$BH$2:$BR$2,$BH3:$BR3,0),0) -> 0 | HB3: =IF(HB$2=InputTable[[#This Row],[Delivery Date]],_xlfn.XLOOKUP(HB$1,$BH$2:$BR$2,$BH3:$BR3,0),0) -> 0 | HC3: =IF(HC$2=InputTable[[#This Row],[Delivery Date]],_xlfn.XLOOKUP(HC$1,$BH$2:$BR$2,$BH3:$BR3,0),0) -> 0 | HD3: =IF(HD$2=InputTable[[#This Row],[Delivery Date]],_xlfn.XLOOKUP(HD$1,$BH$2:$BR$2,$BH3:$BR3,0),0) -> 0 | HF3: =IF(HF$2=InputTable[[#This Row],[Delivery Date]],_xlfn.XLOOKUP(HF$1,$BH$2:$BR$2,$BH3:$BR3,0),0) -> #REF! | HG3: =IF(HG$2=InputTable[[#This Row],[Delivery Date]],_xlfn.XLOOKUP(HG$1,$BH$2:$BR$2,$BH3:$BR3,0),0) -> 0 | HH3: =IF(HH$2=InputTable[[#This Row],[Delivery Date]],_xlfn.XLOOKUP(HH$1,$BH$2:$BR$2,$BH3:$BR3,0),0) -> 0 | HI3: =IF(HI$2=InputTable[[#This Row],[Delivery Date]],_xlfn.XLOOKUP(HI$1,$BH$2:$BR$2,$BH3:$BR3,0),0) -> 0 | HJ3: =IF(HJ$2=InputTable[[#This Row],[Delivery Date]],_xlfn.XLOOKUP(HJ$1,$BH$2:$BR$2,$BH3:$BR3,0),0) -> 0 | HK3: =IF(HK$2=InputTable[[#This Row],[Delivery Date]],_xlfn.XLOOKUP(HK$1,$BH$2:$BR$2,$BH3:$BR3,0),0) -> 0 | HL3: =IF(HL$2=InputTable[[#This Row],[Delivery Date]],_xlfn.XLOOKUP(HL$1,$BH$2:$BR$2,$BH3:$BR3,0),0) -> 0 | HM3: =IF(HM$2=InputTable[[#This Row],[Delivery Date]],_xlfn.XLOOKUP(HM$1,$BH$2:$BR$2,$BH3:$BR3,0),0) -> 0 | HN3: =IF(HN$2=InputTable[[#This Row],[Delivery Date]],_xlfn.XLOOKUP(HN$1,$BH$2:$BR$2,$BH3:$BR3,0),0) -> 0 | HP3: =IF(HP$2=InputTable[[#This Row],[Delivery Date]],_xlfn.XLOOKUP(HP$1,$BH$2:$BR$2,$BH3:$BR3,0),0) -> #REF! | HQ3: =IF(HQ$2=InputTable[[#This Row],[Delivery Date]],_xlfn.XLOOKUP(HQ$1,$BH$2:$BR$2,$BH3:$BR3,0),0) -> 0 | HR3: =IF(HR$2=InputTable[[#This Row],[Delivery Date]],_xlfn.XLOOKUP(HR$1,$BH$2:$BR$2,$BH3:$BR3,0),0) -> 0 | HS3: =IF(HS$2=InputTable[[#This Row],[Delivery Date]],_xlfn.XLOOKUP(HS$1,$BH$2:$BR$2,$BH3:$BR3,0),0) -> 0 | HT3: =IF(HT$2=InputTable[[#This Row],[Delivery Date]],_xlfn.XLOOKUP(HT$1,$BH$2:$BR$2,$BH3:$BR3,0),0) -> 0 | HU3: =IF(HU$2=InputTable[[#This Row],[Delivery Date]],_xlfn.XLOOKUP(HU$1,$BH$2:$BR$2,$BH3:$BR3,0),0) -> 0 | HV3: =IF(HV$2=InputTable[[#This Row],[Delivery Date]],_xlfn.XLOOKUP(HV$1,$BH$2:$BR$2,$BH3:$BR3,0),0) -> 0 | HW3: =IF(HW$2=InputTable[[#This Row],[Delivery Date]],_xlfn.XLOOKUP(HW$1,$BH$2:$BR$2,$BH3:$BR3,0),0) -> 0 | HX3: =IF(HX$2=InputTable[[#This Row],[Delivery Date]],_xlfn.XLOOKUP(HX$1,$BH$2:$BR$2,$BH3:$BR3,0),0) -> 0 | HZ3: =IF(HZ$2=InputTable[[#This Row],[Delivery Date]],_xlfn.XLOOKUP(HZ$1,$BH$2:$BR$2,$BH3:$BR3,0),0) -> #REF! | IA3: =IF(IA$2=InputTable[[#This Row],[Delivery Date]],_xlfn.XLOOKUP(IA$1,$BH$2:$BR$2,$BH3:$BR3,0),0) -> 0 | IB3: =IF(IB$2=InputTable[[#This Row],[Delivery Date]],_xlfn.XLOOKUP(IB$1,$BH$2:$BR$2,$BH3:$BR3,0),0) -> 0 | IC3: =IF(IC$2=InputTable[[#This Row],[Delivery Date]],_xlfn.XLOOKUP(IC$1,$BH$2:$BR$2,$BH3:$BR3,0),0) -> 0 | ID3: =IF(ID$2=InputTable[[#This Row],[Delivery Date]],_xlfn.XLOOKUP(ID$1,$BH$2:$BR$2,$BH3:$BR3,0),0) -> 0 | IE3: =IF(IE$2=InputTable[[#This Row],[Delivery Date]],_xlfn.XLOOKUP(IE$1,$BH$2:$BR$2,$BH3:$BR3,0),0) -> 0 | IF3: =IF(IF$2=InputTable[[#This Row],[Delivery Date]],_xlfn.XLOOKUP(IF$1,$BH$2:$BR$2,$BH3:$BR3,0),0) -> 0 | IG3: =IF(IG$2=InputTable[[#This Row],[Delivery Date]],_xlfn.XLOOKUP(IG$1,$BH$2:$BR$2,$BH3:$BR3,0),0) -> 0 | IH3: =IF(IH$2=InputTable[[#This Row],[Delivery Date]],_xlfn.XLOOKUP(IH$1,$BH$2:$BR$2,$BH3:$BR3,0),0) -> 0 | IJ3: =IF(IJ$2=InputTable[[#This Row],[Delivery Date]],_xlfn.XLOOKUP(IJ$1,$BH$2:$BR$2,$BH3:$BR3,0),0) -> #REF! | IK3: =IF(IK$2=InputTable[[#This Row],[Delivery Date]],_xlfn.XLOOKUP(IK$1,$BH$2:$BR$2,$BH3:$BR3,0),0) -> 0 | IL3: =IF(IL$2=InputTable[[#This Row],[Delivery Date]],_xlfn.XLOOKUP(IL$1,$BH$2:$BR$2,$BH3:$BR3,0),0) -> 0 | IM3: =IF(IM$2=InputTable[[#This Row],[Delivery Date]],_xlfn.XLOOKUP(IM$1,$BH$2:$BR$2,$BH3:$BR3,0),0) -> 0 | IN3: =IF(IN$2=InputTable[[#This Row],[Delivery Date]],_xlfn.XLOOKUP(IN$1,$BH$2:$BR$2,$BH3:$BR3,0),0) -> 0 | IO3: =IF(IO$2=InputTable[[#This Row],[Delivery Date]],_xlfn.XLOOKUP(IO$1,$BH$2:$BR$2,$BH3:$BR3,0),0) -> 0 | IP3: =IF(IP$2=InputTable[[#This Row],[Delivery Date]],_xlfn.XLOOKUP(IP$1,$BH$2:$BR$2,$BH3:$BR3,0),0) -> 0 | IQ3: =IF(IQ$2=InputTable[[#This Row],[Delivery Date]],_xlfn.XLOOKUP(IQ$1,$BH$2:$BR$2,$BH3:$BR3,0),0) -> 0 | IR3: =IF(IR$2=InputTable[[#This Row],[Delivery Date]],_xlfn.XLOOKUP(IR$1,$BH$2:$BR$2,$BH3:$BR3,0),0) -> 0 | IT3: =IF(IT$2=InputTable[[#This Row],[Delivery Date]],_xlfn.XLOOKUP(IT$1,$BH$2:$BR$2,$BH3:$BR3,0),0) -> #REF! | IU3: =IF(IU$2=InputTable[[#This Row],[Delivery Date]],_xlfn.XLOOKUP(IU$1,$BH$2:$BR$2,$BH3:$BR3,0),0) -> 0 | IV3: =IF(IV$2=InputTable[[#This Row],[Delivery Date]],_xlfn.XLOOKUP(IV$1,$BH$2:$BR$2,$BH3:$BR3,0),0) -> 0 | IW3: =IF(IW$2=InputTable[[#This Row],[Delivery Date]],_xlfn.XLOOKUP(IW$1,$BH$2:$BR$2,$BH3:$BR3,0),0) -> 0 | IX3: =IF(IX$2=InputTable[[#This Row],[Delivery Date]],_xlfn.XLOOKUP(IX$1,$BH$2:$BR$2,$BH3:$BR3,0),0) -> 0 | IY3: =IF(IY$2=InputTable[[#This Row],[Delivery Date]],_xlfn.XLOOKUP(IY$1,$BH$2:$BR$2,$BH3:$BR3,0),0) -> 0 | IZ3: =IF(IZ$2=InputTable[[#This Row],[Delivery Date]],_xlfn.XLOOKUP(IZ$1,$BH$2:$BR$2,$BH3:$BR3,0),0) -> 0 | JA3: =IF(JA$2=InputTable[[#This Row],[Delivery Date]],_xlfn.XLOOKUP(JA$1,$BH$2:$BR$2,$BH3:$BR3,0),0) -> 0 | JB3: =IF(JB$2=InputTable[[#This Row],[Delivery Date]],_xlfn.XLOOKUP(JB$1,$BH$2:$BR$2,$BH3:$BR3,0),0) -> 0 | JD3: =IF(JD$2=InputTable[[#This Row],[Delivery Date]],_xlfn.XLOOKUP(JD$1,$BH$2:$BR$2,$BH3:$BR3,0),0) -> #REF! | JE3: =IF(JE$2=InputTable[[#This Row],[Delivery Date]],_xlfn.XLOOKUP(JE$1,$BH$2:$BR$2,$BH3:$BR3,0),0) -> 0 | JF3: =IF(JF$2=InputTable[[#This Row],[Delivery Date]],_xlfn.XLOOKUP(JF$1,$BH$2:$BR$2,$BH3:$BR3,0),0) -> 0 | JG3: =IF(JG$2=InputTable[[#This Row],[Delivery Date]],_xlfn.XLOOKUP(JG$1,$BH$2:$BR$2,$BH3:$BR3,0),0) -> 0 | JH3: =IF(JH$2=InputTable[[#This Row],[Delivery Date]],_xlfn.XLOOKUP(JH$1,$BH$2:$BR$2,$BH3:$BR3,0),0) -> 0 | JI3: =IF(JI$2=InputTable[[#This Row],[Delivery Date]],_xlfn.XLOOKUP(JI$1,$BH$2:$BR$2,$BH3:$BR3,0),0) -> 0 | JJ3: =IF(JJ$2=InputTable[[#This Row],[Delivery Date]],_xlfn.XLOOKUP(JJ$1,$BH$2:$BR$2,$BH3:$BR3,0),0) -> 0 | JK3: =IF(JK$2=InputTable[[#This Row],[Delivery Date]],_xlfn.XLOOKUP(JK$1,$BH$2:$BR$2,$BH3:$BR3,0),0) -> 0 | JL3: =IF(JL$2=InputTable[[#This Row],[Delivery Date]],_xlfn.XLOOKUP(JL$1,$BH$2:$BR$2,$BH3:$BR3,0),0) -> 0 | JN3: =IF(JN$2=InputTable[[#This Row],[Delivery Date]],_xlfn.XLOOKUP(JN$1,$BH$2:$BR$2,$BH3:$BR3,0),0) -> #REF! | JO3: =IF(JO$2=InputTable[[#This Row],[Delivery Date]],_xlfn.XLOOKUP(JO$1,$BH$2:$BR$2,$BH3:$BR3,0),0) -> 0 | JP3: =IF(JP$2=InputTable[[#This Row],[Delivery Date]],_xlfn.XLOOKUP(JP$1,$BH$2:$BR$2,$BH3:$BR3,0),0) -> 0 | JQ3: =IF(JQ$2=InputTable[[#This Row],[Delivery Date]],_xlfn.XLOOKUP(JQ$1,$BH$2:$BR$2,$BH3:$BR3,0),0) -> 0 | JR3: =IF(JR$2=InputTable[[#This Row],[Delivery Date]],_xlfn.XLOOKUP(JR$1,$BH$2:$BR$2,$BH3:$BR3,0),0) -> 0 | JS3: =IF(JS$2=InputTable[[#This Row],[Delivery Date]],_xlfn.XLOOKUP(JS$1,$BH$2:$BR$2,$BH3:$BR3,0),0) -> 0 | JT3: =IF(JT$2=InputTable[[#This Row],[Delivery Date]],_xlfn.XLOOKUP(JT$1,$BH$2:$BR$2,$BH3:$BR3,0),0) -> 0 | JU3: =IF(JU$2=InputTable[[#This Row],[Delivery Date]],_xlfn.XLOOKUP(JU$1,$BH$2:$BR$2,$BH3:$BR3,0),0) -> 0 | JV3: =IF(JV$2=InputTable[[#This Row],[Delivery Date]],_xlfn.XLOOKUP(JV$1,$BH$2:$BR$2,$BH3:$BR3,0),0) -> 0 | JX3: =IF(JX$2=InputTable[[#This Row],[Delivery Date]],_xlfn.XLOOKUP(JX$1,$BH$2:$BR$2,$BH3:$BR3,0),0) -> #REF! | JY3: =IF(JY$2=InputTable[[#This Row],[Delivery Date]],_xlfn.XLOOKUP(JY$1,$BH$2:$BR$2,$BH3:$BR3,0),0) -> 0 | JZ3: =IF(JZ$2=InputTable[[#This Row],[Delivery Date]],_xlfn.XLOOKUP(JZ$1,$BH$2:$BR$2,$BH3:$BR3,0),0) -> 0 | KA3: =IF(KA$2=InputTable[[#This Row],[Delivery Date]],_xlfn.XLOOKUP(KA$1,$BH$2:$BR$2,$BH3:$BR3,0),0) -> 0 | KB3: =IF(KB$2=InputTable[[#This Row],[Delivery Date]],_xlfn.XLOOKUP(KB$1,$BH$2:$BR$2,$BH3:$BR3,0),0) -> 0 | KC3: =IF(KC$2=InputTable[[#This Row],[Delivery Date]],_xlfn.XLOOKUP(KC$1,$BH$2:$BR$2,$BH3:$BR3,0),0) -> 0 | KD3: =IF(KD$2=InputTable[[#This Row],[Delivery Date]],_xlfn.XLOOKUP(KD$1,$BH$2:$BR$2,$BH3:$BR3,0),0) -> 0 | KE3: =IF(KE$2=InputTable[[#This Row],[Delivery Date]],_xlfn.XLOOKUP(KE$1,$BH$2:$BR$2,$BH3:$BR3,0),0) -> 0 | KF3: =IF(KF$2=InputTable[[#This Row],[Delivery Date]],_xlfn.XLOOKUP(KF$1,$BH$2:$BR$2,$BH3:$BR3,0),0) -> 0
